Workbook

Sheet 9KA
A1: adig/1836 | B1: 46017 | C1: 4130 | D1: Glosa : TDC K. ALARCON | E1: KATHERINNE SILVANA ALARCON ESCOBAR | G1: 596065 | H1: -761783 | I1: AÑO ANT | J1: 165718
B2: 46023 | E2: KATHERINNE SILVANA ALARCON ESCOBAR | F2: 165718 | H2: =H1+F2-G2 -> -596065
A3: adig/1864 | B3: 46036 | C3: 4198 | D3: Glosa : Katherinnes credit card payment | E3: KATHERINNE SILVANA ALARCON ESCOBAR | F3: 596065 | H3: =+H2+F3-G3 -> 0
A4: adig/1896 | B4: 46048 | C4: 4247 | D4: Glosa : TDC K. ALARCON | E4: KATHERINNE SILVANA ALARCON ESCOBAR | G4: 1437298 | H4: =+H3+F4-G4 -> -1437298
A5: adig/1914 | B5: 46065 | C5: 4308 | D5: Glosa : Tarjeeta credito Katherinne alarcon | E5: KATHERINNE SILVANA ALARCON ESCOBAR | F5: 1437298 | H5: =+H4+F5-G5 -> 0
A6: adig/1942 | B6: 46078 | C6: 4457 | D6: Glosa : TDC K. ALARCON | E6: KATHERINNE SILVANA ALARCON ESCOBAR | G6: 113423 | H6: =+H5+F6-G6 -> -113423
A7: plib/122 | B7: 46093 | C7: 4435 | D7: Glosa : Pago tarjeta de credito Katherinne Alarcon | E7: KATHERINNE SILVANA ALARCON ESCOBAR | F7: 113423 | H7: =+H6+F7-G7 -> 0
A8: adig/1984 | B8: 46107 | C8: 4596 | D8: Glosa : TDC K. ALARCON | E8: KATHERINNE SILVANA ALARCON ESCOBAR | G8: 2499421 | H8: =+H7+F8-G8 -> -2499421
A14: adig/1836 | B14: 46017 | C14: 4130 | D14: Glosa : TDC K. ALARCON | E14: KATHERINNE SILVANA ALARCON ESCOBAR | G14: 667.63 | H14: =H13+F14-G14 -> -667.63 | I14: =-G14*907.13 -> -605627.2 | J14: =+H1+I14 -> -1367410.2 | K14: ='9X'!O17+'9KA'!J14 -> -167113.2 | L14: diciembre
A15: adig/1896 | B15: 46048 | C15: 4247 | D15: Glosa : TDC K. ALARCON | E15: KATHERINNE SILVANA ALARCON ESCOBAR | F15: 667.63 | H15: =H14+F15-G15 -> 0 | I15: =-H15*865.1 -> 0 | J15: =+H4+I15 -> -1437298 | K15: ='9X'!P19+'9KA'!J15 -> 0 | L15: enero
A16: adig/1942 | B16: 46078 | C16: 4457 | D16: Glosa : TDC K. ALARCON | E16: KATHERINNE SILVANA ALARCON ESCOBAR | G16: 2084.6 | H16: =H15+F16-G16 -> -2084.6 | I16: =H16*871.41 -> -1816541.3 | J16: =+H6+I16 -> -1929964.3 | K16: ='9X'!P26+'9KA'!J16 -> -700.286 | L16: febrero
A17: adig/1984 | B17: 46107 | C17: 4596 | D17: Glosa : TDC K. ALARCON | E17: KATHERINNE SILVANA ALARCON ESCOBAR | G17: 310.21 | H17: =H16+F17-G17 -> -2394.81
A18: adig/1984 | B18: 46107 | C18: 4596 | D18: Glosa : TDC K. ALARCON | E18: KATHERINNE SILVANA ALARCON ESCOBAR | F18: 2084.6 | H18: =H17+F18-G18 -> -310.21 | I18: =H18*927.46 -> -287707.37 | J18: =+H8+I18 -> -2787128.4 | K18: ='9X'!P52+'9KA'!J18 -> -4228.3666 | L18: marzo

Sheet 9X
A1: Account Code | B1: Date | C1: Source | D1: Description | E1: Reference | F1: Debit | G1: Credit
A2: 2114-09 | B2: 46025 | C2: Spend Money | D2: Provision Expenses CC | F2: 0 | G2: 30000 | H2: =+F2-G2 -> -30000
A3: 2114-09 | B3: 46030 | C3: Spend Money | D3: Provision Expenses CC | F3: 0 | G3: 5550 | H3: =H2+F3-G3 -> -35550
A4: 2114-09 | B4: 46036 | C4: Bank Transfer | D4: Bank Transfer from Citibank - CLP to CC Katherinne Alarcon | E4: KA´s credit crd payemnt | F4: 596065 | G4: 0 | H4: =H3+F4-G4 -> 560515
A5: 2114-09 | B5: 46036 | C5: Spend Money | D5: Provision Expenses CC | F5: 0 | G5: 327800 | H5: =H4+F5-G5 -> 232715
A6: 2114-09 | B6: 46036 | C6: Spend Money | D6: Banco De Chile | F6: 0 | G6: 5314.15 | H6: =H5+F6-G6 -> 227400.85
A7: 2114-09 | B7: 46042 | C7: Spend Money | D7: CC Expense | E7: Pasaje a Belo | F7: 0 | G7: 369034 | H7: =H6+F7-G7 -> -141633.15
A8: 2114-09 | B8: 46042 | C8: Spend Money | D8: Provision Expenses CC | F8: 0 | G8: 9774 | H8: =H7+F8-G8 -> -151407.15
A9: 2114-09 | B9: 46042 | C9: Spend Money | D9: Provision Expenses CC | F9: 0 | G9: 13400 | H9: =H8+F9-G9 -> -164807.15
A10: 2114-09 | B10: 46042 | C10: Spend Money | D10: Provision Expenses CC | F10: 0 | G10: 14795 | H10: =H9+F10-G10 -> -179602.15
A11: 2114-09 | B11: 46042 | C11: Spend Money | D11: Provision Expenses CC | F11: 0 | G11: 5550 | H11: =H10+F11-G11 -> -185152.15
A12: 2114-09 | B12: 46042 | C12: Spend Money | D12: Provision Expenses CC | F12: 0 | G12: 8011 | H12: =H11+F12-G12 -> -193163.15
A13: 2114-09 | B13: 46043 | C13: Spend Money | D13: Provision Expenses CC | F13: 0 | G13: 15477 | H13: =H12+F13-G13 -> -208640.15
A14: 2114-09 | B14: 46043 | C14: Spend Money | D14: Provision Expenses CC | F14: 0 | G14: 13833 | H14: =H13+F14-G14 -> -222473.15
A15: 2114-09 | B15: 46044 | C15: Receive Money | D15: Provision Expenses CC | F15: 14795 | G15: 0 | H15: =H14+F15-G15 -> -207678.15
A16: 2114-09 | B16: 46045 | C16: Spend Money | D16: Provision Expenses CC | F16: 0 | G16: 10078 | H16: =H15+F16-G16 -> -217756.15
A17: 2114-09 | B17: 46050 | C17: Spend Money | D17: Banco De Chile | F17: 0 | G17: 402 | H17: =H16+F17-G17 -> -218158.15 | N17: saldo inicial? | O17: =1437298-237001 -> 1200297
A18: 2114-09 | B18: 46050 | C18: Spend Money | D18: Banco De Chile | F18: 0 | G18: 3971 | H18: =H17+F18-G18 -> -222129.15
A19: 2114-09 | B19: 46050 | C19: Spend Money | D19: Banco De Chile | F19: 0 | G19: 14872 | H19: =H18+F19-G19 -> -237001.15 | P19: 1437298
A20: 2114-09 | B20: 46054 | C20: Spend Money | D20: Provision Expenses CC | F20: 0 | G20: 63329 | H20: =((H19 + F20) - G20) -> -300330.15
A21: 2114-09 | B21: 46065 | C21: Bank Transfer | D21: Bank Transfer from Citibank - CLP to CC Katherinne Alarcon | E21: Tarj Créd Kathe Alarcon | F21: 1437298 | G21: 0 | H21: =((H20 + F21) - G21) -> 1136967.9
A22: 2114-09 | B22: 46073 | C22: Spend Money | D22: Joiin Ltda | E22: D30E2B660005 | F22: 0 | G22: 521538.89 | H22: =((H21 + F22) - G22) -> 615428.96
A23: 2114-09 | B23: 46076 | C23: Spend Money | D23: Banco De Chile | F23: 0 | G23: 13239 | H23: =((H22 + F23) - G23) -> 602189.96
A24: 2114-09 | B24: 46077 | C24: Spend Money | D24: Provision Expenses CC | F24: 0 | G24: 1295002.4 | H24: =((H23 + F24) - G24) -> -692812.44
A25: 2114-09 | B25: 46078 | C25: Spend Money | D25: Banco De Chile | F25: 0 | G25: 3977 | H25: =((H24 + F25) - G25) -> -696789.44 | O25: =1929964-729667 -> 1200297
A26: 2114-09 | B26: 46078 | C26: Spend Money | D26: Banco De Chile | F26: 0 | G26: 32878 | H26: =((H25 + F26) - G26) -> -729667.44 | P26: 1929264
A27: 2114-09 | B27: 46092 | C27: Spend Money | D27: Provision Expenses CC | F27: 0 | G27: 275000 | H27: =((H26 + F27) - G27) -> -1004667.4
A28: 2114-09 | B28: 46092 | C28: Spend Money | D28: Provision Expenses CC | F28: 0 | G28: 137176 | H28: =((H27 + F28) - G28) -> -1141843.4
A29: 2114-09 | B29: 46092 | C29: Spend Money | D29: Provision Expenses CC | F29: 0 | G29: 29078 | H29: =((H28 + F29) - G29) -> -1170921.4
A30: 2114-09 | B30: 46092 | C30: Spend Money | D30: Provision Expenses CC | F30: 0 | G30: 10600 | H30: =((H29 + F30) - G30) -> -1181521.4
A31: 2114-09 | B31: 46093 | C31: Bank Transfer | D31: Bank Transfer from Citibank - CLP to CC Katherinne Alarcon | E31: KA´s credit card payemnt | F31: 113423 | G31: 0 | H31: =((H30 + F31) - G31) -> -1068098.4
A32: 2114-09 | B32: 46093 | C32: Spend Money | D32: Banco De Chile | F32: 0 | G32: 122136.71 | H32: =((H31 + F32) - G32) -> -1190235.1
A33: 2114-09 | B33: 46098 | C33: Spend Money | D33: Provision Expenses CC | F33: 0 | G33: 12135.66 | H33: =((H32 + F33) - G33) -> -1202370.8
A34: 2114-09 | B34: 46099 | C34: Spend Money | D34: Banco De Chile | F34: 0 | G34: 309 | H34: =((H33 + F34) - G34) -> -1202679.8
A35: 2114-09 | B35: 46099 | C35: Spend Money | D35: Provision Expenses CC | F35: 0 | G35: 3298.93 | H35: =((H34 + F35) - G35) -> -1205978.7
A36: 2114-09 | B36: 46099 | C36: Spend Money | D36: Provision Expenses CC | F36: 0 | G36: 22242.62 | H36: =((H35 + F36) - G36) -> -1228221.4
A37: 2114-09 | B37: 46099 | C37: Spend Money | D37: Provision Expenses CC | F37: 0 | G37: 50087.02 | H37: =((H36 + F37) - G37) -> -1278308.4
A38: 2114-09 | B38: 46100 | C38: Spend Money | D38: Banco De Chile | F38: 0 | G38: 570 | H38: =((H37 + F38) - G38) -> -1278878.4
A39: 2114-09 | B39: 46100 | C39: Spend Money | D39: Banco De Chile | F39: 0 | G39: 1281 | H39: =((H38 + F39) - G39) -> -1280159.4
A40: 2114-09 | B40: 46100 | C40: Spend Money | D40: Banco De Chile | F40: 0 | G40: 84 | H40: =((H39 + F40) - G40) -> -1280243.4
...

Sheet 11SC
A1: adig/1838 | B1: 46017 | C1: 4132 | D1: Glosa : TDC JS CARVALLO | E1: JUAN SEBASTIAN CARVALLO JIMÉNEZ | G1: 6314 | H1: -40036 | I1: AÑO ANT | J1: 33722
B2: 46023 | E2: JUAN SEBASTIAN CARVALLO JIMÉNEZ | F2: 33722 | H2: =H1+F2-G2 -> -6314
A3: adig/1862 | B3: 46036 | C3: 4196 | D3: Glosa : Credit card payment SC | E3: JUAN SEBASTIAN CARVALLO JIMÉNEZ | F3: 6314 | H3: =H2+F3-G3 -> 0
A4: adig/1894 | B4: 46048 | C4: 4245 | D4: Glosa : TDC CLP JUAN CARVALLO | E4: JUAN SEBASTIAN CARVALLO JIMÉNEZ | G4: 99008 | H4: =H3+F4-G4 -> -99008
A5: adig/1913 | B5: 46065 | C5: 4307 | D5: Glosa : Tarjeta de credito sebastian carballo | E5: JUAN SEBASTIAN CARVALLO JIMÉNEZ | F5: 99008 | H5: =H4+F5-G5 -> 0
A6: adig/1938 | B6: 46078 | C6: 4453 | D6: Glosa : TDC CLP JUAN CARVALLO | E6: JUAN SEBASTIAN CARVALLO JIMÉNEZ | G6: 38514 | H6: =H5+F6-G6 -> -38514
A7: plib/121 | B7: 46093 | C7: 4434 | D7: Glosa : Pago tarjeta de credito Sebastian Carvallo | E7: JUAN SEBASTIAN CARVALLO JIMÉNEZ | F7: 38514 | H7: =H6+F7-G7 -> 0
A8: adig/1983 | B8: 46107 | C8: 4595 | D8: Glosa : TDC CLP JUAN CARVALLO | E8: JUAN SEBASTIAN CARVALLO JIMÉNEZ | G8: 28900 | H8: =H7+F8-G8 -> -28900
A14: 46017 | B14: 4132 | C14: Glosa : TDC JS CARVALLO | D14: JUAN SEBASTIAN CARVALLO JIMÉNEZ | G14: 101.42 | H14: =G13+F14-G14 -> -101.42 | I14: =-G14*907.13 -> -92001.125 | J14: =+I14+H1 -> -132037.12 | K14: ='11X'!N7+'11SC'!J14 -> -33934.125 | L14: diciembre
A15: 46048 | B15: 4245 | C15: Glosa : TDC CLP JUAN CARVALLO | D15: JUAN SEBASTIAN CARVALLO JIMÉNEZ | F15: 101.42 | H15: =H14+F15-G15 -> 0 | I15: =-H15*865.1 -> 0 | J15: =+I15+H4 -> -99008 | K15: ='11X'!O6+'11SC'!J15 -> 0 | L15: enero
A16: adig/1938 | B16: 46078 | C16: 4453 | D16: Glosa : TDC CLP JUAN CARVALLO | E16: JUAN SEBASTIAN CARVALLO JIMÉNEZ | G16: 25.06 | H16: =H15+F16-G16 -> -25.06 | I16: =H16*871.41 -> -21837.535 | J16: =+I16+H6 -> -60351.535 | K16: ='11X'!O11+'11SC'!J16 -> 0.4654 | L16: febrero
A17: adig/1983 | B17: 46107 | C17: 4595 | D17: Glosa : TDC CLP JUAN CARVALLO | E17: JUAN SEBASTIAN CARVALLO JIMÉNEZ | G17: 38.07 | H17: =H16+F17-G17 -> -63.13
A18: adig/1983 | B18: 46107 | C18: 4595 | D18: Glosa : TDC CLP JUAN CARVALLO | E18: JUAN SEBASTIAN CARVALLO JIMÉNEZ | F18: 25.06 | H18: =H17+F18-G18 -> -38.07 | I18: =H18*927.46 -> -35308.402 | J18: =+I18+H8 -> -64208.402 | K18: ='11X'!O22+'11SC'!J18 -> -518.4022 | L18: marzo

Sheet 11X
A1: Account Code | B1: Date | C1: Source | D1: Description | E1: Reference | F1: Debit | G1: Credit
A2: 2114-11 | B2: 46036 | C2: Bank Transfer | D2: Bank Transfer from Citibank - CLP to CC Sebastián Carvallo | E2: SC´s credit card payment | F2: 6314 | G2: 0 | H2: =+F2 -> 6314
A3: 2114-11 | B3: 46036 | C3: Spend Money | D3: Banco De Chile | F3: 0 | G3: 806.84 | H3: =H2+F3-G3 -> 5507.16
A4: 2114-11 | B4: 46050 | C4: Spend Money | D4: Banco De Chile | F4: 0 | G4: 61 | H4: =H3+F4-G4 -> 5446.16
A5: 2114-11 | B5: 46050 | C5: Spend Money | D5: Banco De Chile | F5: 0 | G5: 3971 | H5: =H4+F5-G5 -> 1475.16
A6: 2114-11 | B6: 46050 | C6: Spend Money | D6: Banco De Chile | F6: 0 | G6: 2380 | H6: =H5+F6-G6 -> -904.84 | O6: 99008
A7: 2114-11 | B7: 46065 | C7: Bank Transfer | D7: Bank Transfer from Citibank - CLP to CC Sebastián Carvallo | E7: Tarj Créd Sebastian Carvallo | F7: 99008 | G7: 0 | H7: =((H6 + F7) - G7) -> 98103.16 | M7: salñdo apertura? | N7: =O6-905 -> 98103
A8: 2114-11 | B8: 46069 | C8: Spend Money | D8: Provision Expenses CC | F8: 0 | G8: 33979 | H8: =((H7 + F8) - G8) -> 64124.16
A9: 2114-11 | B9: 46069 | C9: Spend Money | D9: Provision Expenses CC | F9: 0 | G9: 21837.53 | H9: =((H8 + F9) - G9) -> 42286.63
A10: 2114-11 | B10: 46071 | C10: Spend Money | D10: CC Expense | F10: 0 | G10: 558 | H10: =((H9 + F10) - G10) -> 41728.63 | N10: =O11+37752 -> 98104
A11: 2114-11 | B11: 46078 | C11: Spend Money | D11: Banco De Chile | F11: 0 | G11: 3977 | H11: =((H10 + F11) - G11) -> 37751.63 | O11: 60352
A12: 2114-11 | B12: 46082 | C12: Spend Money | D12: Provision Expenses CC | F12: 33979 | G12: 0 | H12: =((H11 + F12) - G12) -> 71730.63
A13: 2114-11 | B13: 46082 | C13: Spend Money | D13: CC Expense | E13: Almuerzo | F13: 0 | G13: 33979 | H13: =((H12 + F13) - G13) -> 37751.63
A14: 2114-11 | B14: 46084 | C14: Spend Money | D14: CC Expense | E14: Cena | F14: 0 | G14: 18176.08 | H14: =((H13 + F14) - G14) -> 19575.55
A15: 2114-11 | B15: 46084 | C15: Spend Money | D15: CC Expense | E15: Desayuno | F15: 0 | G15: 16613.43 | H15: =((H14 + F15) - G15) -> 2962.12
A16: 2114-11 | B16: 46085 | C16: Spend Money | D16: CC Expense | F16: 0 | G16: 420 | H16: =((H15 + F16) - G16) -> 2542.12
A17: 2114-11 | B17: 46085 | C17: Spend Money | D17: CC Expense | F17: 0 | G17: 468 | H17: =((H16 + F17) - G17) -> 2074.12
A18: 2114-11 | B18: 46093 | C18: Bank Transfer | D18: Bank Transfer from Citibank - CLP to CC Sebastián Carvallo | E18: SC´s credit card payemnt | F18: 38514 | G18: 0 | H18: =((H17 + F18) - G18) -> 40588.12
A19: 2114-11 | B19: 46093 | C19: Spend Money | D19: Banco De Chile | F19: 0 | G19: 1468.47 | H19: =((H18 + F19) - G19) -> 39119.65
A20: 2114-11 | B20: 46107 | C20: Spend Money | D20: Banco De Chile | F20: 0 | G20: 15 | H20: =((H19 + F20) - G20) -> 39104.65
A21: 2114-11 | B21: 46107 | C21: Spend Money | D21: Banco De Chile | F21: 0 | G21: 3984 | H21: =((H20 + F21) - G21) -> 35120.65 | N21: =O22+34414 -> 98104
A22: 2114-11 | B22: 46107 | C22: Spend Money | D22: Banco De Chile | F22: 0 | G22: 707 | H22: =((H21 + F22) - G22) -> 34413.65 | O22: 63690

Sheet 12FM
A1: adig/1835 | B1: 46017 | C1: 4129 | D1: Glosa : TDC CLP/USD FRANCISCO MIRANDA | E1: FRANCISCO MIRANDA RIADI | G1: 7314 | H1: -7314 | I1: AÑO ANT
A2: adig/1863 | B2: 46036 | C2: 4197 | D2: Glosa : Bank Transfer to CC Francisco Miranda. | E2: FRANCISCO MIRANDA RIADI | F2: 7314 | H2: =H1+F2-G2 -> 0
A3: adig/1893 | B3: 46048 | C3: 4244 | D3: Glosa : TDC CLP/USD FRANCISCO MIRANDA | E3: FRANCISCO MIRANDA RIADI | G3: 140395 | H3: =H2+F3-G3 -> -140395
A4: adig/1916 | B4: 46065 | C4: 4310 | D4: Glosa : Tarjeta credito francisco miranda | E4: FRANCISCO MIRANDA RIADI | F4: 140395 | H4: =H3+F4-G4 -> 0
A5: adig/1940 | B5: 46078 | C5: 4455 | D5: Glosa : TDC CLP/USD FRANCISCO MIRANDA | E5: FRANCISCO MIRANDA RIADI | G5: 51431 | H5: =H4+F5-G5 -> -51431
A6: plib/120 | B6: 46093 | C6: 4433 | D6: Glosa : Pago Tarjeta de credito Francisco Miranda | E6: FRANCISCO MIRANDA RIADI | F6: 51431 | H6: =H5+F6-G6 -> 0
A7: adig/1985 | B7: 46107 | C7: 4597 | D7: Glosa : TDC CLP/USD FRANCISCO MIRANDA | E7: FRANCISCO MIRANDA RIADI | G7: 98834 | H7: =H6+F7-G7 -> -98834
A13: adig/1835 | B13: 46017 | C13: 4129 | D13: Glosa : TDC CLP/USD FRANCISCO MIRANDA | E13: FRANCISCO MIRANDA RIADI | G13: 144.43 | H13: =-G13 -> -144.43 | I13: =-G13*907.13 -> -131016.79 | J13: =+I13+H1 -> -138330.79 | K13: ='12X'!N13+'12FM'!J13 -> -301.7859 | L13: diciembre
A14: adig/1893 | B14: 46048 | C14: 4244 | D14: Glosa : TDC CLP/USD FRANCISCO MIRANDA | E14: FRANCISCO MIRANDA RIADI | F14: 144.43 | H14: =H13+F14-G14 -> 0
A15: adig/1893 | B15: 46048 | C15: 4244 | D15: Glosa : TDC CLP/USD FRANCISCO MIRANDA | E15: FRANCISCO MIRANDA RIADI | G15: 50.16 | H15: =H14+F15-G15 -> -50.16 | I15: =H15*865.1 -> -43393.416 | J15: =+I15+H3 -> -183788.42 | K15: ='12X'!O14+'12FM'!J15 -> -0.416 | L15: enero
A16: adig/1940 | B16: 46078 | C16: 4455 | D16: Glosa : TDC CLP/USD FRANCISCO MIRANDA | E16: FRANCISCO MIRANDA RIADI | G16: 98.84 | H16: =H15+F16-G16 -> -149
A17: adig/1940 | B17: 46078 | C17: 4455 | D17: Glosa : TDC CLP/USD FRANCISCO MIRANDA | E17: FRANCISCO MIRANDA RIADI | F17: 50.16 | H17: =H16+F17-G17 -> -98.84 | I17: =H17*871.41 -> -86130.164 | J17: =+I17+H5 -> -137561.16 | K17: ='12X'!O29+'12FM'!J17 -> -0.1644 | L17: febrero
A18: adig/1985 | B18: 46107 | C18: 4597 | D18: Glosa : TDC CLP/USD FRANCISCO MIRANDA | E18: FRANCISCO MIRANDA RIADI | F18: 98.84 | H18: =H17+F18-G18 -> 0 | I18: =H18*927.46 -> 0 | J18: =+I18+H7 -> -98834 | K18: ='12X'!O44+'12FM'!J18 -> 0 | L18: marzo

Sheet 12X
A1: Account Code | B1: Date | C1: Source | D1: Description | E1: Reference | F1: Debit | G1: Credit
A2: 2114-12 | B2: 46028 | C2: Spend Money | D2: CC Expense | E2: Impuestro uso aeropuerto Lime Peru | F2: 0 | G2: 10260.05 | H2: =+F2-G2 -> -10260.05
A3: 2114-12 | B3: 46029 | C3: Spend Money | D3: Banco De Chile | F3: 0 | G3: 259 | H3: =H2+F3-G3 -> -10519.05
A4: 2114-12 | B4: 46036 | C4: Bank Transfer | D4: Bank Transfer from Citibank - CLP to CC Francisco Miranda | E4: FM´s credit card payment | F4: 7314 | G4: 0 | H4: =H3+F4-G4 -> -3205.05
A5: 2114-12 | B5: 46036 | C5: Spend Money | D5: Banco De Chile | F5: 0 | G5: 1150.07 | H5: =H4+F5-G5 -> -4355.12
A6: 2114-12 | B6: 46038 | C6: Spend Money | D6: CC Expense | E6: Impuestro uso aeropuerto Lime Peru | F6: 0 | G6: 10260.09 | H6: =H5+F6-G6 -> -14615.21
A7: 2114-12 | B7: 46038 | C7: Spend Money | D7: CC Expense | E7: Almuerzo | F7: 0 | G7: 6012.44 | H7: =H6+F7-G7 -> -20627.65
A8: 2114-12 | B8: 46038 | C8: Spend Money | D8: CC Expense | E8: Cena | F8: 0 | G8: 16860.8 | H8: =H7+F8-G8 -> -37488.45
A9: 2114-12 | B9: 46041 | C9: Spend Money | D9: Banco De Chile | F9: 0 | G9: 258 | H9: =H8+F9-G9 -> -37746.45
A10: 2114-12 | B10: 46042 | C10: Spend Money | D10: Banco De Chile | F10: 0 | G10: 421 | H10: =H9+F10-G10 -> -38167.45
A11: 2114-12 | B11: 46042 | C11: Spend Money | D11: Banco De Chile | F11: 0 | G11: 146 | H11: =H10+F11-G11 -> -38313.45
A12: 2114-12 | B12: 46050 | C12: Spend Money | D12: Banco De Chile | F12: 0 | G12: 87 | H12: =H11+F12-G12 -> -38400.45
A13: 2114-12 | B13: 46050 | C13: Spend Money | D13: Banco De Chile | F13: 0 | G13: 3971 | H13: =H12+F13-G13 -> -42371.45 | N13: =O14-45759 -> 138029
A14: 2114-12 | B14: 46050 | C14: Spend Money | D14: Banco De Chile | F14: 0 | G14: 3388 | H14: =H13+F14-G14 -> -45759.45 | O14: 183788
A15: 2114-12 | B15: 46062 | C15: Spend Money | D15: Provision Expenses CC | F15: 0 | G15: 23083.65 | H15: =((H14 + F15) - G15) -> -68843.1
A16: 2114-12 | B16: 46062 | C16: Spend Money | D16: Provision Expenses CC | F16: 0 | G16: 10334.92 | H16: =((H15 + F16) - G16) -> -79178.02
A17: 2114-12 | B17: 46063 | C17: Spend Money | D17: Banco De Chile | F17: 0 | G17: 266 | H17: =((H16 + F17) - G17) -> -79444.02
A18: 2114-12 | B18: 46065 | C18: Bank Transfer | D18: Bank Transfer from Citibank - CLP to CC Francisco Miranda | E18: Tarj Créd Francisco Miranda | F18: 140395 | G18: 0 | H18: =((H17 + F18) - G18) -> 60950.98
A19: 2114-12 | B19: 46065 | C19: Spend Money | D19: Banco De Chile | F19: 0 | G19: 583 | H19: =((H18 + F19) - G19) -> 60367.98
A20: 2114-12 | B20: 46065 | C20: Spend Money | D20: Banco De Chile | F20: 0 | G20: 747.62 | H20: =((H19 + F20) - G20) -> 59620.36
A21: 2114-12 | B21: 46069 | C21: Spend Money | D21: Provision Expenses CC | F21: 0 | G21: 10334.92 | H21: =((H20 + F21) - G21) -> 49285.44
A22: 2114-12 | B22: 46069 | C22: Spend Money | D22: Provision Expenses CC | F22: 0 | G22: 11650.75 | H22: =((H21 + F22) - G22) -> 37634.69
A23: 2114-12 | B23: 46069 | C23: Spend Money | D23: Provision Expenses CC | F23: 0 | G23: 30725.92 | H23: =((H22 + F23) - G23) -> 6908.77
A24: 2114-12 | B24: 46070 | C24: Spend Money | D24: Banco De Chile | F24: 0 | G24: 266 | H24: =((H23 + F24) - G24) -> 6642.77
A25: 2114-12 | B25: 46072 | C25: Spend Money | D25: Banco De Chile | F25: 0 | G25: 779 | H25: =((H24 + F25) - G25) -> 5863.77
A26: 2114-12 | B26: 46072 | C26: Spend Money | D26: Banco De Chile | F26: 0 | G26: 292 | H26: =((H25 + F26) - G26) -> 5571.77
A27: 2114-12 | B27: 46078 | C27: Spend Money | D27: Banco De Chile | F27: 0 | G27: 29 | H27: =((H26 + F27) - G27) -> 5542.77
A28: 2114-12 | B28: 46078 | C28: Spend Money | D28: Banco De Chile | F28: 0 | G28: 3977 | H28: =((H27 + F28) - G28) -> 1565.77 | N28: =O29+468 -> 138029
A29: 2114-12 | B29: 46078 | C29: Spend Money | D29: Banco De Chile | F29: 0 | G29: 1098 | H29: =((H28 + F29) - G29) -> 467.77 | O29: 137561
A30: 2114-12 | B30: 46082 | C30: Spend Money | D30: CC Expense | E30: Cena | F30: 0 | G30: 30725.92 | H30: =((H29 + F30) - G30) -> -30258.15
A31: 2114-12 | B31: 46082 | C31: Spend Money | D31: CC Expense | E31: Almuerzo | F31: 0 | G31: 11650.75 | H31: =((H30 + F31) - G31) -> -41908.9
A32: 2114-12 | B32: 46082 | C32: Spend Money | D32: CC Expense | E32: Impuesto Aeropuerto | F32: 0 | G32: 10334.92 | H32: =((H31 + F32) - G32) -> -52243.82
A33: 2114-12 | B33: 46082 | C33: Spend Money | D33: CC Expense | E33: Almuerzo | F33: 0 | G33: 23083.65 | H33: =((H32 + F33) - G33) -> -75327.47
A34: 2114-12 | B34: 46082 | C34: Spend Money | D34: CC Expense | E34: Impuesto Aeropuerto | F34: 0 | G34: 10334.92 | H34: =((H33 + F34) - G34) -> -85662.39
A35: 2114-12 | B35: 46082 | C35: Spend Money | D35: Provision Expenses CC | F35: 30725.92 | G35: 0 | H35: =((H34 + F35) - G35) -> -54936.47
A36: 2114-12 | B36: 46082 | C36: Spend Money | D36: Provision Expenses CC | F36: 11650.75 | G36: 0 | H36: =((H35 + F36) - G36) -> -43285.72
A37: 2114-12 | B37: 46082 | C37: Spend Money | D37: Provision Expenses CC | F37: 10334.92 | G37: 0 | H37: =((H36 + F37) - G37) -> -32950.8
A38: 2114-12 | B38: 46082 | C38: Spend Money | D38: Provision Expenses CC | F38: 10334.92 | G38: 0 | H38: =((H37 + F38) - G38) -> -22615.88
A39: 2114-12 | B39: 46082 | C39: Spend Money | D39: Provision Expenses CC | F39: 23083.65 | G39: 0 | H39: =((H38 + F39) - G39) -> 467.77
A40: 2114-12 | B40: 46093 | C40: Bank Transfer | D40: Bank Transfer from Citibank - CLP to CC Francisco Miranda | E40: FM´s credit card payment | F40: 51431 | G40: 0 | H40: =((H39 + F40) - G40) -> 51898.77
...

Sheet 13CW
A1: adig/1833 | B1: 46017 | C1: 4127 | D1: Glosa : TDC CAITLYN WEAT | E1: CAITLIN JOY WHEAT | G1: 1202263 | H1: -1543292 | I1: AÑO ANT | J1: =2580387-2319952 -> 260435
B2: 46023 | E2: CAITLIN JOY WHEAT | F2: 260435 | H2: =H1+F2-G2 -> -1282857
A3: adig/1866 | B3: 46036 | C3: 4200 | D3: Glosa : Credit card payment CW | E3: CAITLIN JOY WHEAT | F3: 1121283 | H3: =H2+F3-G3 -> -161574
A4: adig/1891 | B4: 46050 | C4: 4242 | D4: Glosa : TDC CAITLYN WEAT | E4: CAITLIN JOY WHEAT | G4: 1333628 | H4: =H3+F4-G4 -> -1495202
B5: 46050 | C5: 4321 | D5: Glosa : CC Expense - Oxxo - happy hour | E5: CAITLIN JOY WHEAT | G5: 30700 | H5: =H4+F5-G5 -> -1525902
B6: 46051 | C6: 4319 | D6: Glosa : CC Expense - Cabify para volver a casa despues de dejar el auto arrendado | E6: CAITLIN JOY WHEAT | G6: 11242 | H6: =H5+F6-G6 -> -1537144
B7: 46051 | C7: 4320 | D7: Glosa : CC Expense - Flights Sebastian Carvallo - 16 Feb to 3 march 2026 | E7: CAITLIN JOY WHEAT | G7: 583835 | H7: =H6+F7-G7 -> -2120979
B8: 46065 | G8: 9160 | H8: =H7+F8-G8 -> -2130139
B9: 46065 | C9: 4305 | D9: Glosa : Tarjeta credito caitlin | E9: CAITLIN JOY WHEAT | F9: 1495588 | H9: =H8+F9-G9 -> -634551
B10: 46078 | C10: 4458 | D10: Glosa : TDC CAITLYN WEAT | E10: CAITLIN JOY WHEAT | G10: 1329047 | H10: =H9+F10-G10 -> -1963598
A11: adig/1943 | B11: 46078 | C11: 4458 | D11: Glosa : TDC CAITLYN WEAT | E11: CAITLIN JOY WHEAT | F11: 30702 | H11: =H10+F11-G11 -> -1932896
F12: 11242 | H12: =H11+F12-G12 -> -1921654
F13: 592994 | H13: =H12+F13-G13 -> -1328660
A14: plib/124 | B14: 46093 | C14: 4437 | D14: Glosa : Pago tarjeta de credito Caitlin Wheat | E14: CAITLIN JOY WHEAT | F14: 1159047 | H14: =H13+F14-G14 -> -169613
A15: adig/1986 | B15: 46107 | C15: 4598 | D15: Glosa : TDC CAITLYN WEAT | E15: CAITLIN JOY WHEAT | G15: 2211560 | H15: =H14+F15-G15 -> -2381173
A16: adig/1986 | B16: 46107 | C16: 4598 | D16: Glosa : TDC CAITLYN WEAT | E16: CAITLIN JOY WHEAT | F16: 170000 | H16: =H15+F16-G16 -> -2211173
B17: 46112 | E17: CAITLIN JOY WHEAT | G17: 528200 | H17: =H16+F17-G17 -> -2739373
A20: adig/1833 | B20: 46017 | C20: 4127 | D20: Glosa : TDC CAITLYN WEAT | E20: CAITLIN JOY WHEAT | G20: 48.56 | H20: =-G20 -> -48.56 | I20: =-G20*907.13 -> -44050.233 | J20: =+I20+H1 -> -1587342.2 | K20: ='13X'!N21+'13CW'!J20 -> -260250.23 | L20: diciembre
A21: adig/1891 | B21: 46048 | C21: 4242 | D21: Glosa : TDC CAITLYN WEAT | E21: CAITLIN JOY WHEAT | F21: 48.56 | H21: =H20+F21-G21 -> 0
A22: adig/1891 | B22: 46048 | C22: 4242 | D22: Glosa : TDC CAITLYN WEAT | E22: CAITLIN JOY WHEAT | G22: 230 | H22: =H21+F22-G22 -> -230 | I22: =H22*865.1 -> -198973 | J22: =+I22+H7 -> -2319952 | K22: ='13X'!O22+'13CW'!J22 -> 0 | L22: enero
A23: adig/1943 | B23: 46078 | C23: 4458 | D23: Glosa : TDC CAITLYN WEAT | E23: CAITLIN JOY WHEAT | G23: 1160.03 | H23: =H22+F23-G23 -> -1390.03
A24: adig/1943 | B24: 46078 | C24: 4458 | D24: Glosa : TDC CAITLYN WEAT | E24: CAITLIN JOY WHEAT | F24: 230 | H24: =H23+F24-G24 -> -1160.03 | I24: =H24*871.41 -> -1010861.7 | J24: =+I24+H11 -> -2943757.7 | K24: ='13X'!O48+'13CW'!J24 -> -603848.74 | L24: febrero
A25: adig/1986 | B25: 46107 | C25: 4598 | D25: Glosa : TDC CAITLYN WEAT | E25: CAITLIN JOY WHEAT | G25: 96.1 | H25: =H24+F25-G25 -> -1256.13
A26: adig/1986 | B26: 46107 | C26: 4598 | D26: Glosa : TDC CAITLYN WEAT | E26: CAITLIN JOY WHEAT | F26: 1160.03 | H26: =H25+F26-G26 -> -96.1 | I26: =H26*927.46 -> -89128.906 | J26: =+I26+H17 -> -2828501.9 | K26: ='13X'!O88+'13CW'!J26 -> -922.906 | L26: marzo

Sheet 13X
A1: Account Code | B1: Date | C1: Source | D1: Description | E1: Reference | F1: Debit | G1: Credit
A2: 2114-13 | B2: 46027 | C2: Payable Payment | D2: Payment: Telefonica Chile S.A (Movistar) | E2: 54133203 | F2: 0 | G2: 304961 | H2: =-G2 -> -304961
A3: 2114-13 | B3: 46027 | C3: Spend Money | D3: CC Expense | E3: Dulceria Praline - Birthday cakes - Katherinne and Denisse | F3: 0 | G3: 57550 | H3: =H2+F3-G3 -> -362511
A4: 2114-13 | B4: 46027 | C4: Payable Payment | D4: Payment: Telefonica Chile S.A (Movistar) | E4: F/50708669 | F4: 0 | G4: 24003 | H4: =H3+F4-G4 -> -386514
A5: 2114-13 | B5: 46027 | C5: Spend Money | D5: CC Expense | E5: Cafe Diario 5976 + Justo- Catering clients in the office | F5: 0 | G5: 20900 | H5: =H4+F5-G5 -> -407414
A6: 2114-13 | B6: 46028 | C6: Spend Money | D6: CC Expense | E6: Coca Cola - drinks for the office | F6: 0 | G6: 138250 | H6: =H5+F6-G6 -> -545664
A7: 2114-13 | B7: 46028 | C7: Spend Money | D7: CC Expense | E7: Artifood - healthy snacks | F7: 0 | G7: 30840 | H7: =H6+F7-G7 -> -576504
A8: 2114-13 | B8: 46028 | C8: Spend Money | D8: BECKER PADRUNO GRATTINI Y COMPANIA LTDA | F8: 0 | G8: 97164 | H8: =H7+F8-G8 -> -673668
A9: 2114-13 | B9: 46029 | C9: Spend Money | D9: CC Expense | E9: Unimarc - snacks / milk for office | F9: 0 | G9: 22550 | H9: =H8+F9-G9 -> -696218
A10: 2114-13 | B10: 46029 | C10: Spend Money | D10: CC Expense | E10: My Home - homewares for the office | F10: 0 | G10: 38110 | H10: =H9+F10-G10 -> -734328
A11: 2114-13 | B11: 46035 | C11: Receive Money | D11: CC Expense | F11: 80980 | G11: 0 | H11: =H10+F11-G11 -> -653348
A12: 2114-13 | B12: 46036 | C12: Bank Transfer | D12: Bank Transfer from Citibank - CLP to CC Caitlin Wheat | E12: CW´s credit card payemnt | F12: 1121283 | G12: 0 | H12: =H11+F12-G12 -> 467935
A13: 2114-13 | B13: 46042 | C13: Spend Money | D13: CC Expense | E13: Municipalidad Las Condes - Patente 1er semestre | F13: 0 | G13: 496021 | H13: =H12+F13-G13 -> -28086
A14: 2114-13 | B14: 46042 | C14: Spend Money | D14: CC Expense | E14: GMG Forum - Tickets for Carolina Toro and Marcelo Penna | F14: 0 | G14: 198973 | H14: =H13+F14-G14 -> -227059
A15: 2114-13 | B15: 46043 | C15: Spend Money | D15: CC Expense | E15: Sodimac - dispensador de agua para la oficina | F15: 0 | G15: 129980 | H15: =H14+F15-G15 -> -357039
A16: 2114-13 | B16: 46043 | C16: Spend Money | D16: Banco De Chile | F16: 0 | G16: 4945 | H16: =H15+F16-G16 -> -361984
A17: 2114-13 | B17: 46050 | C17: Spend Money | D17: CC Expense | E17: Oxxo - happy hour | F17: 0 | G17: 30700 | H17: =H16+F17-G17 -> -392684
A18: 2114-13 | B18: 46050 | C18: Spend Money | D18: Banco De Chile | F18: 0 | G18: 3971 | H18: =H17+F18-G18 -> -396655
A19: 2114-13 | B19: 46050 | C19: Spend Money | D19: Banco De Chile | F19: 0 | G19: 1099 | H19: =H18+F19-G19 -> -397754
A20: 2114-13 | B20: 46050 | C20: Spend Money | D20: Banco De Chile | F20: 0 | G20: 29 | H20: =H19+F20-G20 -> -397783
A21: 2114-13 | B21: 46051 | C21: Spend Money | D21: CC Expense | E21: Flights Sebastian Carvallo - 16 Feb to 3 march 2026 | F21: 0 | G21: 583834.97 | H21: =H20+F21-G21 -> -981617.97 | M21: saldo apertura | N21: =O22-992860 -> 1327092
A22: 2114-13 | B22: 46051 | C22: Spend Money | D22: CC Expense | E22: Cabify para volver a casa despues de dejar el auto arrendado | F22: 0 | G22: 11242 | H22: =H21+F22-G22 -> -992859.97 | O22: 2319952
A23: 2114-13 | B23: 46054 | C23: Spend Money | D23: CC Expense | F23: 0 | G23: 9159.53 | H23: =H22+F23-G23 -> -1002019.5
A24: 2114-13 | B24: 46054 | C24: Spend Money | D24: Banco De Chile | F24: 0 | G24: 15054 | H24: =((H23 + F24) - G24) -> -1017073.5
A25: 2114-13 | B25: 46055 | C25: Spend Money | D25: CC Expense | E25: Mi Coca Cola - Drinks for the office | F25: 0 | G25: 116100 | H25: =((H24 + F25) - G25) -> -1133173.5
A26: 2114-13 | B26: 46055 | C26: Spend Money | D26: CC Expense | E26: Artifood - Healthy snacks for the office | F26: 0 | G26: 30840 | H26: =((H25 + F26) - G26) -> -1164013.5
A27: 2114-13 | B27: 46055 | C27: Spend Money | D27: CC Expense | E27: Confiteria - Snacks for the office | F27: 0 | G27: 37797 | H27: =((H26 + F27) - G27) -> -1201810.5
A28: 2114-13 | B28: 46055 | C28: Spend Money | D28: CC Expense | E28: Enjoy Antofagasta - Cena mujeres - Accommodation for Carolina Toro and Marcelo Penna | F28: 0 | G28: 289691.54 | H28: =((H27 + F28) - G28) -> -1491502
A29: 2114-13 | B29: 46056 | C29: Spend Money | D29: Banco De Chile | F29: 0 | G29: 7354 | H29: =((H28 + F29) - G29) -> -1498856
A30: 2114-13 | B30: 46057 | C30: Spend Money | D30: CC Expense | E30: Unimarc - yoghurt for the office | F30: 0 | G30: 40010 | H30: =((H29 + F30) - G30) -> -1538866
A31: 2114-13 | B31: 46062 | C31: Payable Payment | D31: Payment: Telefonica Chile S.A (Movistar) | E31: 54139621 | F31: 0 | G31: 304745 | H31: =((H30 + F31) - G31) -> -1843611
A32: 2114-13 | B32: 46062 | C32: Payable Payment | D32: Payment: Telefonica Chile S.A (Movistar) | E32: F/50708669 | F32: 0 | G32: 24003 | H32: =((H31 + F32) - G32) -> -1867614
A33: 2114-13 | B33: 46063 | C33: Spend Money | D33: CC Expense | E33: Cabify - Marcelo Penna - Meeting - Unicorn Consulting | F33: 0 | G33: 6027 | H33: =((H32 + F33) - G33) -> -1873641
A34: 2114-13 | B34: 46063 | C34: Spend Money | D34: CC Expense | E34: Cabify - Marcelo Penna - Home from meeting (Unicorn Consulting) | F34: 0 | G34: 6391 | H34: =((H33 + F34) - G34) -> -1880032
A35: 2114-13 | B35: 46063 | C35: Spend Money | D35: CC Expense | E35: Office supplies - ream of paper for sales team | F35: 0 | G35: 18970 | H35: =((H34 + F35) - G35) -> -1899002
A36: 2114-13 | B36: 46065 | C36: Bank Transfer | D36: Bank Transfer from Citibank - CLP to CC Caitlin Wheat | E36: Tarj Créd Caitlin Wheat | F36: 1495588 | G36: 0 | H36: =((H35 + F36) - G36) -> -403414.04
A37: 2114-13 | B37: 46065 | C37: Spend Money | D37: CC Expense | E37: Cabify - Carolina Toro - visita a GG Gardilcic | F37: 0 | G37: 5943 | H37: =((H36 + F37) - G37) -> -409357.04
A38: 2114-13 | B38: 46065 | C38: Spend Money | D38: Banco De Chile | F38: 0 | G38: 3812.82 | H38: =((H37 + F38) - G38) -> -413169.86
A39: 2114-13 | B39: 46070 | C39: Spend Money | D39: CC Expense | E39: Cabify - Carolina Toro - Reunin con Mitsubishi | F39: 0 | G39: 6592 | H39: =((H38 + F39) - G39) -> -419761.86
A40: 2114-13 | B40: 46070 | C40: Spend Money | D40: CC Expense | E40: Cabify - Carolina Toro - Mitsubishi | F40: 0 | G40: 6637 | H40: =((H39 + F40) - G40) -> -426398.86
...

Sheet 14CM
A1: adig/1834 | B1: 46017 | C1: 4128 | D1: Glosa : TDC CESAR MACHADO | E1: CESAR FELIPE MACHADO RIBEIRO LOPES | H1: 719990 | I1: -719990
A2: adig/1865 | B2: 46036 | C2: 4199 | D2: Glosa : Credit Card payment CM | E2: CESAR FELIPE MACHADO RIBEIRO LOPES | G2: 719990 | I2: =I1+G2-H2 -> 0
A3: adig/1892 | B3: 46048 | C3: 4243 | D3: Glosa : TDC CESAR MACHADO | E3: CESAR FELIPE MACHADO RIBEIRO LOPES | H3: 86888 | I3: =I2+G3-H3 -> -86888
A4: adig/1915 | B4: 46065 | C4: 4309 | D4: Glosa : Tarjeta credito Cesar Machado | E4: CESAR FELIPE MACHADO RIBEIRO LOPES | G4: 86888 | I4: =I3+G4-H4 -> 0
I5: =I4+G5-H5 -> 0
A10: adig/1834 | B10: 46017 | C10: 4128 | D10: Glosa : TDC CESAR MACHADO | E10: CESAR FELIPE MACHADO RIBEIRO LOPES | H10: 88.56 | I10: =I9+G10-H10 -> -88.56 | J10: =-H10*907.13 -> -80335.433 | K10: =+J10+I1 -> -800325.43 | L10: ='14X'!N5+'14CM'!K10 -> -185.4328 | M10: diciembre
A11: adig/1892 | B11: 46048 | C11: 4243 | D11: Glosa : TDC CESAR MACHADO | E11: CESAR FELIPE MACHADO RIBEIRO LOPES | G11: 88.56 | I11: =I10+G11-H11 -> 0 | J11: =I11*865.1 -> 0 | K11: =+J11+I3 -> -86888 | L11: ='14X'!O6+'14CM'!K11 -> 0 | M11: enero
I12: 0 | J12: =I12*871.41 -> 0 | K12: =+J12+I4 -> 0 | L12: ='14X'!O8+'14CM'!K12 -> 0 | M12: febrero
I13: 0 | J13: =I13*927.46 -> 0 | K13: =+J13+I5 -> 0 | L13: ='14X'!O10+'14CM'!K13 -> 0 | M13: marzo

Sheet 14X
A1: Account Code | B1: Date | C1: Source | D1: Description | E1: Reference | F1: Debit | G1: Credit
A2: 2114-14 | B2: 46036 | C2: Bank Transfer | D2: Bank Transfer from Citibank - CLP to CC Cesar Machado | F2: 719990 | G2: 0 | H2: =+F2 -> 719990
A3: 2114-14 | B3: 46036 | C3: Spend Money | D3: Banco De Chile | F3: 0 | G3: 704.66 | H3: =H2+F3-G3 -> 719285.34
A4: 2114-14 | B4: 46050 | C4: Spend Money | D4: Banco De Chile | F4: 0 | G4: 53 | H4: =H3+F4-G4 -> 719232.34
A5: 2114-14 | B5: 46050 | C5: Spend Money | D5: Banco De Chile | F5: 0 | G5: 3971 | H5: =H4+F5-G5 -> 715261.34 | N5: =O6+713252 -> 800140
A6: 2114-14 | B6: 46050 | C6: Spend Money | D6: Banco De Chile | F6: 0 | G6: 2009 | H6: =H5+F6-G6 -> 713252.34 | O6: 86888
A7: 2114-14 | B7: 46065 | C7: Bank Transfer | D7: Bank Transfer from Citibank - CLP to CC Cesar Machado | E7: Tarj Créd Cesar Machado | F7: 86888 | G7: 0 | H7: =H6+F7-G7 -> 800140.34 | N7: =O8+800140 -> 800140
H8: =H7+F8-G8 -> 800140.34 | O8: 0
N9: =O10+840140 -> 840140
O10: 0

Sheet 15JM
A1: adig/1813 | B1: 46017 | C1: 4062 | D1: Glosa : 25.12 - Reimbursable Expense - Gastos Frigobar Hot... | 25.12 - Reimbursable Expense - Gastos Frigobar Hot... | E1: JORGE MORIS JORDÁN | F1: 71962 | H1: 71962 | I1: AÑO ANT | K1: =1349829-1277867 -> 71962
B2: 46023 | E2: JORGE MORIS JORDÁN | G2: 71962 | H2: =H1+F2-G2 -> 0
A3: adig/1897 | B3: 46049 | C3: 4316 | D3: Glosa : CC Expense - Estacionamiento 27 enero | E3: JORGE MORIS JORDÁN | G3: 14910 | H3: =H2+F3-G3 -> -14910
B4: 46051 | C4: 4317 | D4: Glosa : CC Expense - Combustible semana 3 | E4: JORGE MORIS JORDÁN | G4: 46725 | H4: =H3+F4-G4 -> -61635
B5: 46053 | C5: 4249 | D5: Glosa : TDC CLP/USD JORGE MORIS | E5: JORGE MORIS JORDÁN | G5: 303651 | H5: =H4+F5-G5 -> -365286 | I5: =+H1 -> 71962 | J5: ='15X'!N17+'15JM'!I5 -> 71962 | K5: diciembre
B6: 46053 | C6: 4322 | D6: Glosa : Pago F1770256 Serpab en tdc | E6: JORGE MORIS JORDÁN | G6: 984543 | H6: =H5+F6-G6 -> -1349829 | I6: =+H6 -> -1349829 | J6: ='15X'!O19+'15JM'!I6 -> 0 | K6: enero
A7: adig/1917 | B7: 46065 | C7: 4311 | D7: Glosa : Tarjeta de credito jorge moris | E7: JORGE MORIS JORDÁN | F7: 303651 | H7: =H6+F7-G7 -> -1046178
A8: adig/1939 | B8: 46078 | C8: 4454 | D8: Glosa : TDC CLP/USD JORGE MORIS | E8: JORGE MORIS JORDÁN | G8: 1050155 | H8: =H7+F8-G8 -> -2096333
A9: adig/1939 | B9: 46078 | C9: 4454 | D9: Glosa : TDC CLP/USD JORGE MORIS | E9: JORGE MORIS JORDÁN | F9: 984543 | H9: =H8+F9-G9 -> -1111790
B10: 46078 | C10: 4454 | D10: Glosa : TDC CLP/USD JORGE MORIS | E10: JORGE MORIS JORDÁN | F10: 14910 | H10: =H9+F10-G10 -> -1096880
A11: adig/1939 | B11: 46078 | C11: 4454 | D11: Glosa : TDC CLP/USD JORGE MORIS | E11: JORGE MORIS JORDÁN | F11: 46725 | H11: =H10+F11-G11 -> -1050155 | I11: =+H11 -> -1050155 | J11: ='15X'!O21+'15JM'!I11 -> 0 | K11: febrero
A12: plib/123 | B12: 46093 | C12: 4436 | D12: Glosa : Pago tarjeta de credito Jorge Moris | E12: JORGE MORIS JORDÁN | F12: 1050155 | H12: =H11+F12-G12 -> 0 | I12: =+H12 -> 0 | J12: ='15X'!O22+'15JM'!I12 -> 0 | K12: marzo

Sheet 15X
A1: Account Code | B1: Date | C1: Source | D1: Description | E1: Reference | F1: Debit | G1: Credit
A2: 2114-15 | B2: 46034 | C2: Spend Money | D2: CC Expense | E2: Estacionamiento 12 enero | F2: 0 | G2: 14730 | H2: =-G2 -> -14730
A3: 2114-15 | B3: 46035 | C3: Spend Money | D3: CC Expense | E3: Estacionamiento 13 enero | F3: 0 | G3: 14130 | H3: =H2+F3-G3 -> -28860
A4: 2114-15 | B4: 46036 | C4: Spend Money | D4: CC Expense | E4: Estacionamiento 14 enero | F4: 0 | G4: 13980 | H4: =H3+F4-G4 -> -42840
A5: 2114-15 | B5: 46036 | C5: Spend Money | D5: CC Expense | E5: Combustible semana 1 | F5: 0 | G5: 48655 | H5: =H4+F5-G5 -> -91495
A6: 2114-15 | B6: 46037 | C6: Spend Money | D6: CC Expense | E6: Estacionamiento 15 enero | F6: 0 | G6: 15180 | H6: =H5+F6-G6 -> -106675
A7: 2114-15 | B7: 46037 | C7: Spend Money | D7: CC Expense | E7: Chocolates para entrenamientos | F7: 0 | G7: 9390 | H7: =H6+F7-G7 -> -116065
A8: 2114-15 | B8: 46041 | C8: Spend Money | D8: CC Expense | E8: Estacionamiento 19 enero | F8: 0 | G8: 14220 | H8: =H7+F8-G8 -> -130285
A9: 2114-15 | B9: 46042 | C9: Spend Money | D9: CC Expense | E9: Combustible semana 2 | F9: 0 | G9: 49715 | H9: =H8+F9-G9 -> -180000
A10: 2114-15 | B10: 46042 | C10: Spend Money | D10: CC Expense | E10: Estacionamiento 20 enero | F10: 0 | G10: 13410 | H10: =H9+F10-G10 -> -193410
A11: 2114-15 | B11: 46043 | C11: Spend Money | D11: CC Expense | E11: Estacionamiento 21 enero | F11: 0 | G11: 14700 | H11: =H10+F11-G11 -> -208110
A12: 2114-15 | B12: 46044 | C12: Spend Money | D12: CC Expense | E12: Estacionamiento 22 enero | F12: 0 | G12: 13710 | H12: =H11+F12-G12 -> -221820
A13: 2114-15 | B13: 46048 | C13: Spend Money | D13: CC Expense | E13: Combustible semana 3 | F13: 0 | G13: 48880 | H13: =H12+F13-G13 -> -270700
A14: 2114-15 | B14: 46048 | C14: Spend Money | D14: CC Expense | E14: Estacionamiento 26 enero | F14: 0 | G14: 14070 | H14: =H13+F14-G14 -> -284770
... A16: 2114-15 | B16: 46050 | C16: Spend Money | D16: CC Expense | E16: Estacionamiento 28 enero | F16: 0 | G16: 14910 | H16: =H15+F16-G16 -> -314590
A17: 2114-15 | B17: 46050 | C17: Spend Money | D17: Banco De Chile | F17: 0 | G17: 3971 | H17: =H16+F17-G17 -> -318561 | N17: =O19-1349829 -> 0
A18: 2114-15 | B18: 46051 | C18: Spend Money | D18: CC Expense | E18: Combustible semana 3 | F18: 0 | G18: 46725 | H18: =H17+F18-G18 -> -365286
A19: 2114-15 | B19: 46052 | C19: Spend Money | D19: CC Expense | E19: F1770256 Serpab / Arriendo Auto | F19: 0 | G19: 984543 | H19: =H18+F19-G19 -> -1349829 | O19: 1349829 | P19: =O19-1349829 -> 0
A20: 2114-15 | B20: 46065 | C20: Bank Transfer | D20: Bank Transfer from Citibank - CLP to CC Jorge Moris | E20: Tarj Créd Jorge Moris | F20: 303651 | G20: 0 | H20: =((H19 + F20) - G20) -> -1046178
A21: 2114-15 | B21: 46078 | C21: Spend Money | D21: Banco De Chile | F21: 0 | G21: 3977 | H21: =((H20 + F21) - G21) -> -1050155 | O21: 1050155 | P21: =O21-1050155 -> 0
A22: 2114-15 | B22: 46093 | C22: Bank Transfer | D22: Bank Transfer from Citibank - CLP to CC Jorge Moris | E22: JM´s credit card payment | F22: 1050155 | G22: 0 | H22: =((H21 + F22) - G22) -> 0 | O22: 0 | P22: =O22-0 -> 0

Sheet 54MP
A1: adig/1837 | B1: 46017 | C1: 4131 | D1: Glosa : TDC M. PENNA | E1: MARCELO PENNA SANTOS | G1: 752789 | H1: -752789 | L1: =+H1+'15JM'!H1+'14CM'!I1+'13CW'!H1+'12FM'!H1+'11SC'!H1+'9KA'!H1 -> -3753242 | M1: DICIEMBRE
A2: adig/1861 | B2: 46036 | C2: 4195 | D2: Glosa : Credit Card payment MP | E2: MARCELO PENNA SANTOS | F2: 752789 | H2: =H1+F2-G2 -> 0
A3: adig/1895 | B3: 46048 | C3: 4246 | D3: Glosa : TDC M. PENNA | E3: MARCELO PENNA SANTOS | G3: 146634 | H3: =H2+F3-G3 -> -146634 | L3: =+H3+'15JM'!H3+'14CM'!I3+'13CW'!H4+'12FM'!H3+'11SC'!H4+'9KA'!H4-217460 -> -3637795 | M3: ENERO
A4: adig/1912 | B4: 46065 | C4: 4306 | D4: Glosa : Tarjeta credito Marcelo Penna | E4: MARCELO PENNA SANTOS | F4: 146634 | H4: =H3+F4-G4 -> 0
A5: adig/1941 | B5: 46078 | C5: 4456 | D5: Glosa : TDC M. PENNA | E5: MARCELO PENNA SANTOS | G5: 44849 | H5: =H4+F5-G5 -> -44849
A6: plib/125 | B6: 46093 | C6: 4438 | D6: Glosa : Pago tarjeta de credito Caitlin Wheat | E6: MARCELO PENNA SANTOS | F6: 44849 | H6: =H5+F6-G6 -> 0
A7: adig/1982 | B7: 46107 | C7: 4594 | D7: Glosa : TDC M. PENNA | E7: MARCELO PENNA SANTOS | G7: 775062 | H7: =H6+F7-G7 -> -775062 | I7: =+H7+'15JM'!I12+'14CM'!I5+'13CW'!H17+'12FM'!H7+'11SC'!H8+'9KA'!H8 -> -6141590
A13: adig/1837 | B13: 46017 | C13: 4131 | D13: Glosa : TDC M. PENNA | E13: MARCELO PENNA SANTOS | G13: 103.08 | H13: =H12+F13-G13 -> -103.08 | I13: =-G13*907.13 -> -93506.96 | J13: =+I13+H1 -> -846295.96 | K13: ='54X'!N76+'54MP'!J13 -> -195913.96 | L13: diciembre | M13: =+H13+'14CM'!I10+'13CW'!H20+'12FM'!H13+'11SC'!H14+'9KA'!H14 -> -1153.68 | N13: =+I13+'14CM'!J10+'13CW'!I20+'12FM'!I13+'11SC'!I14+'9KA'!I14 -> -1046537.7 | O13: =+J13+'14CM'!K10+'13CW'!J20+'12FM'!J13+'11SC'!J14+'9KA'!J14+'15JM'!H1 -> -4799779.7 | P13: DICIEMBRE
A14: adig/1895 | B14: 46048 | C14: 4246 | D14: Glosa : TDC M. PENNA | E14: MARCELO PENNA SANTOS | F14: 103.08 | H14: =H13+F14-G14 -> 0 | I14: =H14*865.1 -> 0 | J14: =+I14+H3 -> -146634 | K14: ='54X'!O77+'54MP'!J14 -> 1203195 | L14: enero | M14: =+H14+'14CM'!I11+'13CW'!H22+'12FM'!H15+'11SC'!H15+'9KA'!H15 -> -280.16 | N14: =M14*865.1 -> -242366.42 | O14: =+L3+N14 -> -3880161.4 | P14: ENERO
A15: adig/1941 | B15: 46078 | C15: 4456 | D15: Glosa : TDC M. PENNA | E15: MARCELO PENNA SANTOS | G15: 472 | H15: =H14+F15-G15 -> -472 | I15: =H15*871.41 -> -411305.52 | J15: =+I15+H5 -> -456154.52 | K15: ='54X'!O102+'54MP'!J15 -> -1.52 | L15: febrero
A16: adig/1982 | B16: 46107 | C16: 4594 | D16: Glosa : TDC M. PENNA | E16: MARCELO PENNA SANTOS | G16: 240.84 | H16: =H15+F16-G16 -> -712.84
A17: adig/1982 | B17: 46107 | C17: 4594 | D17: Glosa : TDC M. PENNA | E17: MARCELO PENNA SANTOS | F17: 472 | H17: =H16+F17-G17 -> -240.84 | I17: =H17*927.46 -> -223369.47 | J17: =+I17+H7 -> -998431.47 | K17: ='54X'!O131+'54MP'!J17 -> -3282.4664 | L17: marzo

Sheet 54X
A1: Account Code | B1: Date | C1: Source | D1: Description | E1: Reference | F1: Debit | G1: Credit
A2: 2114-54 | B2: 46023 | C2: Spend Money | D2: CC Expense | E2: Taxi - Airport - House | F2: 0 | G2: 33648.88 | H2: =-G2 -> -33648.88
A3: 2114-54 | B3: 46023 | C3: Spend Money | D3: CC Expense | E3: Water Airport | F3: 0 | G3: 3753.84 | H3: =H2+F3-G3 -> -37402.72
A4: 2114-54 | B4: 46023 | C4: Spend Money | D4: CC Expense | E4: Uber - House - Office | F4: 0 | G4: 4857.37 | H4: =H3+F4-G4 -> -42260.09
A5: 2114-54 | B5: 46023 | C5: Spend Money | D5: CC Expense | E5: Uber - Office - House | F5: 0 | G5: 4188.02 | H5: =H4+F5-G5 -> -46448.11
A6: 2114-54 | B6: 46023 | C6: Spend Money | D6: CC Expense | E6: Uber - House - Office | F6: 0 | G6: 6829.27 | H6: =H5+F6-G6 -> -53277.38
A7: 2114-54 | B7: 46023 | C7: Spend Money | D7: CC Expense | E7: Uber - Happy Hour - House | F7: 0 | G7: 5282.51 | H7: =H6+F7-G7 -> -58559.89
A8: 2114-54 | B8: 46023 | C8: Spend Money | D8: CC Expense | E8: Uber - House - Amadoria | F8: 0 | G8: 7290.59 | H8: =H7+F8-G8 -> -65850.48
A9: 2114-54 | B9: 46023 | C9: Spend Money | D9: CC Expense | E9: Uber - Office - House | F9: 0 | G9: 5635.28 | H9: =H8+F9-G9 -> -71485.76
A10: 2114-54 | B10: 46023 | C10: Spend Money | D10: CC Expense | E10: Uber - Office - House | F10: 0 | G10: 4359.88 | H10: =H9+F10-G10 -> -75845.64
A11: 2114-54 | B11: 46023 | C11: Spend Money | D11: CC Expense | E11: Uber - House - Olympics | F11: 0 | G11: 3545.79 | H11: =H10+F11-G11 -> -79391.43
A12: 2114-54 | B12: 46023 | C12: Spend Money | D12: CC Expense | E12: Uber to Deswik Party | F12: 0 | G12: 8963.99 | H12: =H11+F12-G12 -> -88355.42
A13: 2114-54 | B13: 46023 | C13: Spend Money | D13: CC Expense | E13: Uber - Olympics - House | F13: 0 | G13: 4884.51 | H13: =H12+F13-G13 -> -93239.93
A14: 2114-54 | B14: 46023 | C14: Spend Money | D14: CC Expense | E14: Lunch Marcelo and Jorge in Rancagua | F14: 0 | G14: 16500 | H14: =H13+F14-G14 -> -109739.93
... A35: 2114-54 | B35: 46023 | C35: Spend Money | D35: CC Expense | E35: Uber - Home - SCL | F35: 0 | G35: 31519 | H35: =H34+F35-G35 -> -1247429.9
A36: 2114-54 | B36: 46023 | C36: Receive Money | D36: Provision Expenses CC | F36: 16500 | G36: 0 | H36: =H35+F36-G36 -> -1230929.9
A37: 2114-54 | B37: 46023 | C37: Receive Money | D37: Provision Expenses CC | F37: 23400 | G37: 0 | H37: =H36+F37-G37 -> -1207529.9
A38: 2114-54 | B38: 46023 | C38: Receive Money | D38: Provision Expenses CC | F38: 139700 | G38: 0 | H38: =H37+F38-G38 -> -1067829.9
A39: 2114-54 | B39: 46023 | C39: Receive Money | D39: Provision Expenses CC | F39: 13600 | G39: 0 | H39: =H38+F39-G39 -> -1054229.9
A40: 2114-54 | B40: 46023 | C40: Receive Money | D40: Provision Expenses CC | F40: 3600 | G40: 0 | H40: =H39+F40-G40 -> -1050629.9
A41: 2114-54 | B41: 46023 | C41: Receive Money | D41: Provision Expenses CC | F41: 115170 | G41: 0 | H41: =H40+F41-G41 -> -935459.93
A42: 2114-54 | B42: 46023 | C42: Receive Money | D42: Provision Expenses CC | F42: 29000 | G42: 0 | H42: =H41+F42-G42 -> -906459.93
A43: 2114-54 | B43: 46023 | C43: Receive Money | D43: Provision Expenses CC | F43: 8400 | G43: 0 | H43: =H42+F43-G43 -> -898059.93
A44: 2114-54 | B44: 46023 | C44: Receive Money | D44: Provision Expenses CC | F44: 2600 | G44: 0 | H44: =H43+F44-G44 -> -895459.93
A45: 2114-54 | B45: 46023 | C45: Receive Money | D45: Provision Expenses CC | F45: 2600 | G45: 0 | H45: =H44+F45-G45 -> -892859.93
A46: 2114-54 | B46: 46023 | C46: Receive Money | D46: Provision Expenses CC | F46: 24200 | G46: 0 | H46: =H45+F46-G46 -> -868659.93
A47: 2114-54 | B47: 46023 | C47: Receive Money | D47: Provision Expenses CC | F47: 29000 | G47: 0 | H47: =H46+F47-G47 -> -839659.93
... A69: 2114-54 | B69: 46023 | C69: Receive Money | D69: Provision Expenses CC | F69: 4884.51 | G69: 0 | H69: =H68+F69-G69 -> 7.2759576e-11
A70: 2114-54 | B70: 46036 | C70: Bank Transfer | D70: Bank Transfer from Citibank - CLP to CC Marcelo Penna | E70: Credit Card payment | F70: 752789 | H70: =H69+F70-G70 -> 752789
A71: 2114-54 | B71: 46036 | C71: Spend Money | D71: Banco De Chile | G71: 820.48 | H71: =H70+F71-G71 -> 751968.52
A72: 2114-54 | B72: 46042 | C72: Spend Money | D72: Provision Expenses CC | F72: 0 | G72: 4963 | H72: =H71+F72-G72 -> 747005.52
A73: 2114-54 | B73: 46042 | C73: Spend Money | D73: Provision Expenses CC | F73: 0 | G73: 26290 | H73: =H72+F73-G73 -> 720715.52
A74: 2114-54 | B74: 46045 | C74: Spend Money | D74: Provision Expenses CC | F74: 0 | G74: 14898 | H74: =H73+F74-G74 -> 705817.52
A75: 2114-54 | B75: 46050 | C75: Spend Money | D75: Banco De Chile | F75: 0 | G75: 62 | H75: =H74+F75-G75 -> 705755.52
A76: 2114-54 | B76: 46050 | C76: Spend Money | D76: Banco De Chile | F76: 0 | G76: 3971 | H76: =H75+F76-G76 -> 701784.52 | N76: =1349829-699447 -> 650382
A77: 2114-54 | B77: 46050 | C77: Spend Money | D77: Banco De Chile | F77: 0 | G77: 2338 | H77: =H76+F77-G77 -> 699446.52 | O77: 1349829
A78: 2114-54 | B78: 46065 | C78: Bank Transfer | D78: Bank Transfer from Citibank - CLP to CC Marcelo Penna | E78: Tarj Créd Marcelo Penna | F78: 146634 | G78: 0 | H78: =((H77 + F78) - G78) -> 846080.52
A79: 2114-54 | B79: 46069 | C79: Spend Money | D79: Provision Expenses CC | F79: 0 | G79: 10334.92 | H79: =((H78 + F79) - G79) -> 835745.6
A80: 2114-54 | B80: 46069 | C80: Spend Money | D80: Provision Expenses CC | F80: 0 | G80: 10334.92 | H80: =((H79 + F80) - G80) -> 825410.68
A81: 2114-54 | B81: 46070 | C81: Spend Money | D81: Banco De Chile | F81: 0 | G81: 265 | H81: =((H80 + F81) - G81) -> 825145.68
...

Sheet Hoja1
A1: 9 | B1: AÑO ANT | C1: 165718 | K1: -1603016 | L1: =+'9KA'!H1+'11SC'!H1+'12FM'!H1+'13CW'!H1+'14CM'!I1+'15JM'!H1+'54MP'!H1 -> -3753242 | M1: clp
A2: 11 | B2: AÑO ANT | C2: 33722 | K2: -132730 | L2: =+'9KA'!I14+'11SC'!I14+'12FM'!I13+'13CW'!I20+'14CM'!J10+'54MP'!I13 -> -1046537.7 | M2: usd
A3: 12 | B3: AÑO ANT | K3: -183788.42
A4: 13 | B4: AÑO ANT | C4: 260435 | K4: -2580387
A5: 14 | K5: -86888
A6: 15 | B6: AÑO ANT | D6: =1349829-1277867 -> 71962 | K6: -1277867
A7: 54 | B7: AÑO ANT | K7: -146634
A8: S/A | B8: AÑO ANT | C8: 217461 | K8: -217461
C9: =SUM(C1:C8) -> 677336 | D9: =SUM(D1:D7) -> 71962 | K9: =SUM(K1:K8) -> -6228771.4
C10: DIF | D10: =C9-D9 -> 605374
