Workbook

Sheet TDC
A1: Comprobante | B1: Fec. Doc. | C1: Voucher | E1: Titular | F1: T.Doc/Nro | G1: Debe | H1: Haber | I1: Acumulado
A2: adig/1114 | B2: 45772 | C2: 2553 | D2: Glosa : TDC CLP_USD C.Contreras | E2: CAROL TATIANA CONTRERAS MUÑOZ | H2: 3070443 | I2: -3070443
A3: adig/1115 | B3: 45772 | C3: 2554 | D3: Glosa : TDC CLP Marcelo PENNA | E3: MARCELO PENNA SANTOS | H3: 494703 | I3: -3565146
A4: adig/1116 | B4: 45772 | C4: 2555 | D4: Glosa : TDC CLP JUAN CARVALLO | E4: JUAN CARVALLO JIMÉNEZ | H4: 122074 | I4: -3687220
A5: adig/1117 | B5: 45772 | C5: 2556 | D5: Glosa : TDC CLP-USD CAITLIN WHEAT | E5: CAITLIN JOY WHEAT | H5: 100022 | I5: -3787242
A6: adig/1122 | B6: 45772 | C6: 2561 | D6: Glosa : TDC CLP-USD CAtherine alaracon | E6: KATHERINNE SILVANA ALARCON ESCOBAR | H6: 806870 | I6: -4594112
A7: adig/1283 | B7: 45772 | C7: 2939 | D7: Glosa : TDC CLP/USD FRANCISCO MIRANDA | E7: FRANCISCO MIRANDA RIADI | H7: 5014 | I7: -4599126
A8: adig/1170 | B8: 45792 | C8: 2742 | D8: Glosa : Bank Transfer to CC Caitlin Wheat. | E8: CAITLIN JOY WHEAT | G8: 100022 | I8: -4499104
A9: adig/1171 | B9: 45792 | C9: 2743 | D9: Glosa : Bank Transfer to CC Carol Contreras. | E9: CAROL TATIANA CONTRERAS MUÑOZ | G9: 3070443 | I9: -1428661
A10: adig/1172 | B10: 45792 | C10: 2744 | D10: Glosa : Bank Transfer to CC Katherinne Alarcon. | E10: KATHERINNE SILVANA ALARCON ESCOBAR | G10: 806870 | I10: -621791
A11: adig/1173 | B11: 45792 | C11: 2745 | D11: Glosa : Bank Transfer to CC Francisco Miranda. | E11: FRANCISCO MIRANDA RIADI | G11: 5014 | I11: -616777
A12: adig/1174 | B12: 45792 | C12: 2746 | D12: Glosa : Bank Transfer to CC Sebastián Carvallo. | E12: JUAN CARVALLO JIMÉNEZ | G12: 72314 | I12: -544463
A13: adig/1175 | B13: 45792 | C13: 2749 | D13: Glosa : Bank Transfer to CC Marcelo Penna. | E13: MARCELO PENNA SANTOS | G13: 1901018 | I13: 1356555
A14: adig/1250 | B14: 45805 | C14: 2906 | D14: Glosa : TDC CLP-USD CAITLIN WHEAT | E14: CAITLIN JOY WHEAT | H14: 211905 | I14: 1144650
A15: adig/1251 | B15: 45805 | C15: 2907 | D15: Glosa : TDC CLP_USD C.Contreras | E15: CAROL TATIANA CONTRERAS MUÑOZ | H15: 1231423 | I15: -86773
A16: adig/1252 | B16: 45805 | C16: 2908 | D16: Glosa : Tarjeta de Credito F.Miranda | E16: FRANCISCO MIRANDA RIADI | H16: 71087 | I16: -157860
A17: adig/1253 | B17: 45805 | C17: 2909 | D17: Glosa : TDC pesos USD Katherine Alarcon | E17: KATHERINNE SILVANA ALARCON ESCOBAR | H17: 100449 | I17: -258309
A18: adig/1254 | B18: 45805 | C18: 2910 | D18: Glosa : TDC CLP/USD Marcelo PENNA | E18: MARCELO PENNA SANTOS | H18: 79021 | I18: -337330
A19: adig/1255 | B19: 45805 | C19: 2911 | D19: Glosa : TDC CLP JUAN sebastian CARVALLO | E19: JUAN CARVALLO JIMÉNEZ | H19: 161109 | I19: -498439
A20: adig/1284 | B20: 45805 | C20: 2940 | D20: Glosa : TDC CLP/USD CESAR MACHADO | E20: CESAR FELIPE MACHADO RIBEIRO LOPES | H20: 51519 | I20: -549958
A21: adig/1553 | B21: 45805 | C21: 3504 | D21: Glosa : TDC CLP JUAN sebastian CARVALLO | E21: JUAN CARVALLO JIMÉNEZ | H21: 229285 | I21: -779243
A22: adig/1196 | B22: 45810 | C22: 2822 | D22: Glosa : Prepaid PPE seguridad | E22: DEMO MAGNUS ERP | H22: 25228 | I22: -804471
A23: adig/1202 | B23: 45820 | C23: 2858 | D23: Glosa : Bank Transfer to CC Caitlin Wheat. | E23: CAITLIN JOY WHEAT | G23: 450611 | I23: -353860
A24: adig/1203 | B24: 45820 | C24: 2859 | D24: Glosa : Bank Transfer to CC Katherinne Alarcon. | E24: KATHERINNE SILVANA ALARCON ESCOBAR | G24: 100449 | I24: -253411
A25: adig/1204 | B25: 45820 | C25: 2860 | D25: Glosa : Bank Transfer to CC Francisco Miranda. | E25: FRANCISCO MIRANDA RIADI | G25: 71087 | I25: -182324
A26: adig/1205 | B26: 45820 | C26: 2861 | D26: Glosa : Bank Transfer to CC Marcelo Penna. | E26: MARCELO PENNA SANTOS | G26: 79021 | I26: -103303
A27: adig/1206 | B27: 45820 | C27: 2862 | D27: Glosa : Bank Transfer to CC Sebastián Carvallo. | E27: JUAN CARVALLO JIMÉNEZ | G27: 210396 | I27: 107093
A28: adig/1207 | B28: 45820 | C28: 2863 | D28: Glosa : Bank Transfer to CC Carol Contreras. | E28: CAROL TATIANA CONTRERAS MUÑOZ | G28: 1231423 | I28: 1338516
A29: adig/1256 | B29: 45834 | C29: 2912 | D29: Glosa : TDC CLP/USD CARLO CONTRERAS | E29: CAROL TATIANA CONTRERAS MUÑOZ | H29: 981428 | I29: 357088
A30: adig/1257 | B30: 45834 | C30: 2913 | D30: Glosa : TDC CLP/USD CESAR MACHADO | E30: CESAR FELIPE MACHADO RIBEIRO LOPES | H30: 1962244 | I30: -1605156
A31: adig/1258 | B31: 45834 | C31: 2914 | D31: Glosa : TDC CLP/USD FRANCISCO MIRANDA | E31: FRANCISCO MIRANDA RIADI | H31: 4322 | I31: -1609478
A32: adig/1259 | B32: 45834 | C32: 2915 | D32: Glosa : TDC CLP/USD JORGE MORIS | E32: JORGE MORIS JORDÁN | H32: 39636 | I32: -1649114
A33: adig/1260 | B33: 45834 | C33: 2916 | D33: Glosa : TDC CLP/USD KATHERINE ALARCON | E33: KATHERINNE SILVANA ALARCON ESCOBAR | H33: 2020460 | I33: -3669574
A34: adig/1261 | B34: 45834 | C34: 2917 | D34: Glosa : TDC CLP/USD MARCELO PENNA | E34: MARCELO PENNA SANTOS | H34: 87617 | I34: -3757191
A35: adig/1311 | B35: 45845 | C35: 3041 | D35: Glosa : Payment: ER - Carol Contreras 25.7 - Reimbursable Expense - compra cervezas happ... | 25.7 - Reimbursable Expense - compra cervezas happ... | E35: CAROL TATIANA CONTRERAS MUÑOZ | G35: 33059 | I35: -3724132
A36: adig/1312 | B36: 45848 | C36: 3049 | D36: Glosa : Bank Transfer to CC Carol Contreras. | E36: CAROL TATIANA CONTRERAS MUÑOZ | G36: 981428 | I36: -2742704
A37: adig/1313 | B37: 45848 | C37: 3050 | D37: Glosa : Bank Transfer to CC Katherinne Alarcon. | E37: KATHERINNE SILVANA ALARCON ESCOBAR | G37: 2020460 | I37: -722244
A38: adig/1314 | B38: 45848 | C38: 3051 | D38: Glosa : Bank Transfer to CC Francisco Miranda. | E38: FRANCISCO MIRANDA RIADI | G38: 20216 | I38: -702028
A39: adig/1315 | B39: 45848 | C39: 3052 | D39: Glosa : Bank Transfer to CC Marcelo Penna. | E39: MARCELO PENNA SANTOS | G39: 87617 | I39: -614411
A40: adig/1333 | B40: 45867 | C40: 3092 | D40: Glosa : TDC CLP/USD CAROl CONTRERAS | E40: CAROL TATIANA CONTRERAS MUÑOZ | H40: 1861875 | I40: -2476286
...

Sheet 06102025
A1: Comprobante | B1: Fec. Doc. | C1: Voucher | E1: Titular | F1: Debe | G1: Haber | H1: Acumulado
A2: plib/8 | B2: 45750 | C2: 2493 | D2: Glosa : reembolso Marcelo Penna | E2: MARCELO PENNA SANTOS | F2: 121678 | H2: 121678
A3: adig/1114 | B3: 45772 | C3: 2553 | D3: Glosa : TDC CLP_USD C.Contreras | E3: CAROL TATIANA CONTRERAS MUÑOZ | G3: 3070443 | H3: -2948765
A4: adig/1115 | B4: 45772 | C4: 2554 | D4: Glosa : TDC CLP Marcelo PENNA | E4: MARCELO PENNA SANTOS | G4: 494703 | H4: -3443468
A5: adig/1116 | B5: 45772 | C5: 2555 | D5: Glosa : TDC CLP JUAN CARVALLO | E5: JUAN CARVALLO JIMÉNEZ | G5: 122074 | H5: -3565542
A6: adig/1117 | B6: 45772 | C6: 2556 | D6: Glosa : TDC CLP-USD CAITLIN WHEAT | E6: CAITLIN JOY WHEAT | G6: 100022 | H6: -3665564
A7: adig/1122 | B7: 45772 | C7: 2561 | D7: Glosa : TDC CLP-USD CAtherine alaracon | E7: KATHERINNE SILVANA ALARCON ESCOBAR | G7: 806870 | H7: -4472434
A8: adig/1283 | B8: 45772 | C8: 2939 | D8: Glosa : TDC CLP/USD FRANCISCO MIRANDA | E8: FRANCISCO MIRANDA RIADI | G8: 5014 | H8: -4477448
A9: adig/1161 | B9: 45785 | C9: 2721 | D9: Glosa : Payment: ER - Marcelo Penna25.4 - Reimbursable Expense - Apr 2025 - Reimbursa... | E9: MARCELO PENNA SANTOS | F9: 22780 | H9: -4454668
A10: adig/1163 | B10: 45785 | C10: 2723 | D10: Glosa : Payment: ER - Katherinne Alarcon25.3 - Reimbursable Expense - Viaje Lima | 25.3 - Reimbursable Expense - Viaje Lima | E10: KATHERINNE SILVANA ALARCON ESCOBAR | F10: 15336 | H10: -4439332
A11: adig/1170 | B11: 45792 | C11: 2742 | D11: Glosa : Bank Transfer to CC Caitlin Wheat. | E11: CAITLIN JOY WHEAT | F11: 100022 | H11: -4339310
A12: adig/1171 | B12: 45792 | C12: 2743 | D12: Glosa : Bank Transfer to CC Carol Contreras. | E12: CAROL TATIANA CONTRERAS MUÑOZ | F12: 3070443 | H12: -1268867
A13: adig/1172 | B13: 45792 | C13: 2744 | D13: Glosa : Bank Transfer to CC Katherinne Alarcon. | E13: KATHERINNE SILVANA ALARCON ESCOBAR | F13: 806870 | H13: -461997
A14: adig/1173 | B14: 45792 | C14: 2745 | D14: Glosa : Bank Transfer to CC Francisco Miranda. | E14: FRANCISCO MIRANDA RIADI | F14: 5014 | H14: -456983
A15: adig/1174 | B15: 45792 | C15: 2746 | D15: Glosa : Bank Transfer to CC Sebastián Carvallo. | E15: JUAN CARVALLO JIMÉNEZ | F15: 72314 | H15: -384669
A16: adig/1175 | B16: 45792 | C16: 2749 | D16: Glosa : Bank Transfer to CC Marcelo Penna. | E16: MARCELO PENNA SANTOS | F16: 1901018 | H16: 1516349
A17: adig/1250 | B17: 45805 | C17: 2906 | D17: Glosa : TDC CLP-USD CAITLIN WHEAT | E17: CAITLIN JOY WHEAT | G17: 450611 | H17: 1065738
A18: adig/1251 | B18: 45805 | C18: 2907 | D18: Glosa : TDC CLP_USD C.Contreras | E18: CAROL TATIANA CONTRERAS MUÑOZ | G18: 1231423 | H18: -165685
A19: adig/1252 | B19: 45805 | C19: 2908 | D19: Glosa : Tarjeta de Credito F.Miranda | E19: FRANCISCO MIRANDA RIADI | G19: 71087 | H19: -236772
A20: adig/1253 | B20: 45805 | C20: 2909 | D20: Glosa : TDC pesos USD Katherine Alarcon | E20: KATHERINNE SILVANA ALARCON ESCOBAR | G20: 100449 | H20: -337221
A21: adig/1254 | B21: 45805 | C21: 2910 | D21: Glosa : TDC CLP/USD Marcelo PENNA | E21: MARCELO PENNA SANTOS | G21: 79021 | H21: -416242
A22: adig/1255 | B22: 45805 | C22: 2911 | D22: Glosa : TDC CLP JUAN sebastian CARVALLO | E22: JUAN CARVALLO JIMÉNEZ | G22: 161109 | H22: -577351
A23: adig/1284 | B23: 45805 | C23: 2940 | D23: Glosa : TDC CLP/USD CESAR MACHADO | E23: CESAR FELIPE MACHADO RIBEIRO LOPES | G23: 51519 | H23: -628870
A24: adig/1553 | B24: 45805 | C24: 3504 | D24: Glosa : TDC CLP JUAN sebastian CARVALLO | E24: JUAN CARVALLO JIMÉNEZ | G24: 229285 | H24: -858155
A25: adig/1187 | B25: 45813 | C25: 2810 | D25: Glosa : Payment: multiple itemsReembolsos Caroline Zorzi | E25: carolina zorzi | F25: 36610 | H25: -821545
A26: adig/1189 | B26: 45813 | C26: 2812 | D26: Glosa : Payment: ER - Jorge Moris25.4 - Reimbursable Expense - Vacuna Influenza | 25.4 - Reimbursable Expense - Vacuna Influenza | E26: JORGE MORIS JORDÁN | F26: 19500 | H26: -802045
A27: adig/1190 | B27: 45813 | C27: 2813 | D27: Glosa : Payment: ER - Caitlin Wheat25.5 - Reimbursable Expense - Reimbursement May 20... | 25.5 - Reimbursable Expense - Reimbursement May 20... | E27: CAITLIN JOY WHEAT | F27: 2300 | H27: -799745
A28: adig/1191 | B28: 45813 | C28: 2814 | D28: Glosa : Payment: ER - Sebastián Carvallo25.5 - Reimbursable Expense - Lundin Mining - Cand... | 25.5 - Reimbursable Expense - Lundin Mining - Cand... | E28: JUAN CARVALLO JIMÉNEZ | F28: 43000 | H28: -756745
A29: adig/1192 | B29: 45813 | C29: 2815 | D29: Glosa : Payment: ER - Marcelo Penna25.5 - Reimbursable Expense - Candelaria Site Visi... | 25.5 - Reimbursable Expense - Candelaria Site Visi... | E29: MARCELO PENNA SANTOS | F29: 20000 | H29: -736745
A30: adig/1202 | B30: 45820 | C30: 2858 | D30: Glosa : Bank Transfer to CC Caitlin Wheat. | E30: CAITLIN JOY WHEAT | F30: 450611 | H30: -286134
A31: adig/1203 | B31: 45820 | C31: 2859 | D31: Glosa : Bank Transfer to CC Katherinne Alarcon. | E31: KATHERINNE SILVANA ALARCON ESCOBAR | F31: 100449 | H31: -185685
A32: adig/1204 | B32: 45820 | C32: 2860 | D32: Glosa : Bank Transfer to CC Francisco Miranda. | E32: FRANCISCO MIRANDA RIADI | F32: 71087 | H32: -114598
A33: adig/1205 | B33: 45820 | C33: 2861 | D33: Glosa : Bank Transfer to CC Marcelo Penna. | E33: MARCELO PENNA SANTOS | F33: 79021 | H33: -35577
A34: adig/1206 | B34: 45820 | C34: 2862 | D34: Glosa : Bank Transfer to CC Sebastián Carvallo. | E34: JUAN CARVALLO JIMÉNEZ | F34: 210396 | H34: 174819
A35: adig/1207 | B35: 45820 | C35: 2863 | D35: Glosa : Bank Transfer to CC Carol Contreras. | E35: CAROL TATIANA CONTRERAS MUÑOZ | F35: 1231423 | H35: 1406242
A36: adig/1194 | B36: 45834 | C36: 2817 | D36: Glosa : Payment: ER - Jorge Moris25.6 - Reimbursable Expense - Estacionamiento Mine... | E36: JORGE MORIS JORDÁN | F36: 9000 | H36: 1415242
A37: adig/1256 | B37: 45834 | C37: 2912 | D37: Glosa : TDC CLP/USD CARLO CONTRERAS | E37: CAROL TATIANA CONTRERAS MUÑOZ | G37: 981428 | H37: 433814
A38: adig/1257 | B38: 45834 | C38: 2913 | D38: Glosa : TDC CLP/USD CESAR MACHADO | E38: CESAR FELIPE MACHADO RIBEIRO LOPES | G38: 1962244 | H38: -1528430
A39: adig/1258 | B39: 45834 | C39: 2914 | D39: Glosa : TDC CLP/USD FRANCISCO MIRANDA | E39: FRANCISCO MIRANDA RIADI | G39: 4322 | H39: -1532752
A40: adig/1259 | B40: 45834 | C40: 2915 | D40: Glosa : TDC CLP/USD JORGE MORIS | E40: JORGE MORIS JORDÁN | G40: 39636 | H40: -1572388
...

Sheet 07102025
A1: Comprobante | B1: Fec. Doc. | C1: Voucher | E1: Titular | F1: T.Doc/Nro | G1: Debe | H1: Haber | I1: Acumulado
A2: adig/991 | B2: 45693 | C2: 2278 | D2: Glosa : Pago Tarjeta de Credito | E2: KATHERINNE SILVANA ALARCON ESCOBAR | G2: 1611355 | I2: 1611355
A3: adig/993 | B3: 45693 | C3: 2280 | D3: Glosa : Pago Tarjeta de Credito | E3: MARCELO PENNA SANTOS | G3: 3652188 | I3: 5263543
A4: adig/994 | B4: 45701 | C4: 2281 | D4: Glosa : Pago Tarjeta de Credito | E4: CAITLIN JOY WHEAT | G4: 260913 | I4: 5524456
A5: adig/995 | B5: 45701 | C5: 2282 | D5: Glosa : Pago Tarjeta de Credito | E5: JUAN CARVALLO JIMÉNEZ | G5: 650343 | I5: 6174799
A6: adig/996 | B6: 45701 | C6: 2283 | D6: Glosa : Pago Tarjeta de Credito | E6: FRANCISCO MIRANDA RIADI | G6: 181839 | I6: 6356638
A7: adig/997 | B7: 45701 | C7: 2284 | D7: Glosa : Pago Tarjeta de Credito | E7: KATHERINNE SILVANA ALARCON ESCOBAR | G7: 1777290 | I7: 8133928
A8: adig/1053 | B8: 45729 | C8: 2342 | D8: Glosa : Pago tarjeta de Credito | E8: CAITLIN JOY WHEAT | G8: 3872 | I8: 8137800
A9: adig/1054 | B9: 45729 | C9: 2343 | D9: Glosa : Pago tarjeta de Credito | E9: JUAN CARVALLO JIMÉNEZ | G9: 20962 | I9: 8158762
A10: adig/1055 | B10: 45729 | C10: 2344 | D10: Glosa : Pago tarjeta de Credito | E10: FRANCISCO MIRANDA RIADI | G10: 819483 | I10: 8978245
A11: plib/8 | B11: 45750 | C11: 2493 | D11: Glosa : reembolso Marcelo Penna | E11: MARCELO PENNA SANTOS | G11: 121678 | I11: 9099923
A12: plib/22 | B12: 45762 | C12: 2508 | D12: Glosa : Pago tarjeta de credio Francisco Miranda | E12: FRANCISCO MIRANDA RIADI | G12: 221541 | I12: 9321464
A13: plib/23 | B13: 45762 | C13: 2509 | D13: Glosa : Pago tarjeta de credito Katherinne Alarcon | E13: KATHERINNE SILVANA ALARCON ESCOBAR | G13: 46444 | I13: 9367908
... A16: plib/26 | B16: 45762 | C16: 2512 | D16: Glosa : Pago Tarjeta de credito Marcelo Penna | E16: MARCELO PENNA SANTOS | G16: 2623654 | I16: 13794176
A17: adig/1114 | B17: 45772 | C17: 2553 | D17: Glosa : TDC CLP_USD C.Contreras | E17: CAROL TATIANA CONTRERAS MUÑOZ | H17: 3070443 | I17: 10723733
A18: adig/1115 | B18: 45772 | C18: 2554 | D18: Glosa : TDC CLP Marcelo PENNA | E18: MARCELO PENNA SANTOS | H18: 1901018 | I18: 8822715
A19: adig/1116 | B19: 45772 | C19: 2555 | D19: Glosa : TDC CLP JUAN CARVALLO | E19: JUAN CARVALLO JIMÉNEZ | H19: 122074 | I19: 8700641
A20: adig/1117 | B20: 45772 | C20: 2556 | D20: Glosa : TDC CLP-USD CAITLIN WHEAT | E20: CAITLIN JOY WHEAT | H20: 100022 | I20: 8600619
A21: adig/1122 | B21: 45772 | C21: 2561 | D21: Glosa : TDC CLP-USD CAtherine alaracon | E21: KATHERINNE SILVANA ALARCON ESCOBAR | H21: 806870 | I21: 7793749
A22: adig/1283 | B22: 45772 | C22: 2939 | D22: Glosa : TDC CLP/USD FRANCISCO MIRANDA | E22: FRANCISCO MIRANDA RIADI | H22: 5014 | I22: 7788735
A23: adig/1161 | B23: 45785 | C23: 2721 | D23: Glosa : Payment: ER - Marcelo Penna25.4 - Reimbursable Expense - Apr 2025 - Reimbursa... | E23: MARCELO PENNA SANTOS | G23: 22780 | I23: 7811515
A24: adig/1163 | B24: 45785 | C24: 2723 | D24: Glosa : Payment: ER - Katherinne Alarcon25.3 - Reimbursable Expense - Viaje Lima | 25.3 - Reimbursable Expense - Viaje Lima | E24: KATHERINNE SILVANA ALARCON ESCOBAR | G24: 15336 | I24: 7826851
A25: adig/1170 | B25: 45792 | C25: 2742 | D25: Glosa : Bank Transfer to CC Caitlin Wheat. | E25: CAITLIN JOY WHEAT | G25: 100022 | I25: 7926873
A26: adig/1171 | B26: 45792 | C26: 2743 | D26: Glosa : Bank Transfer to CC Carol Contreras. | E26: CAROL TATIANA CONTRERAS MUÑOZ | G26: 3070443 | I26: 10997316
A27: adig/1172 | B27: 45792 | C27: 2744 | D27: Glosa : Bank Transfer to CC Katherinne Alarcon. | E27: KATHERINNE SILVANA ALARCON ESCOBAR | G27: 806870 | I27: 11804186
A28: adig/1173 | B28: 45792 | C28: 2745 | D28: Glosa : Bank Transfer to CC Francisco Miranda. | E28: FRANCISCO MIRANDA RIADI | G28: 5014 | I28: 11809200
A29: adig/1174 | B29: 45792 | C29: 2746 | D29: Glosa : Bank Transfer to CC Sebastián Carvallo. | E29: JUAN CARVALLO JIMÉNEZ | G29: 72314 | I29: 11881514
A30: adig/1175 | B30: 45792 | C30: 2749 | D30: Glosa : Bank Transfer to CC Marcelo Penna. | E30: MARCELO PENNA SANTOS | G30: 1901018 | I30: 13782532
A31: adig/1250 | B31: 45805 | C31: 2906 | D31: Glosa : TDC CLP-USD CAITLIN WHEAT | E31: CAITLIN JOY WHEAT | H31: 450611 | I31: 13331921
A32: adig/1251 | B32: 45805 | C32: 2907 | D32: Glosa : TDC CLP_USD C.Contreras | E32: CAROL TATIANA CONTRERAS MUÑOZ | H32: 1231423 | I32: 12100498
A33: adig/1252 | B33: 45805 | C33: 2908 | D33: Glosa : Tarjeta de Credito F.Miranda | E33: FRANCISCO MIRANDA RIADI | H33: 71087 | I33: 12029411
A34: adig/1253 | B34: 45805 | C34: 2909 | D34: Glosa : TDC pesos USD Katherine Alarcon | E34: KATHERINNE SILVANA ALARCON ESCOBAR | H34: 100449 | I34: 11928962
A35: adig/1254 | B35: 45805 | C35: 2910 | D35: Glosa : TDC CLP/USD Marcelo PENNA | E35: MARCELO PENNA SANTOS | H35: 79021 | I35: 11849941
A36: adig/1255 | B36: 45805 | C36: 2911 | D36: Glosa : TDC CLP JUAN sebastian CARVALLO | E36: JUAN CARVALLO JIMÉNEZ | H36: 161109 | I36: 11688832
A37: adig/1284 | B37: 45805 | C37: 2940 | D37: Glosa : TDC CLP/USD CESAR MACHADO | E37: CESAR FELIPE MACHADO RIBEIRO LOPES | H37: 51519 | I37: 11637313
A38: adig/1553 | B38: 45805 | C38: 3504 | D38: Glosa : TDC CLP JUAN sebastian CARVALLO | E38: JUAN CARVALLO JIMÉNEZ | H38: 229285 | I38: 11408028
A39: adig/1187 | B39: 45813 | C39: 2810 | D39: Glosa : Payment: multiple itemsReembolsos Caroline Zorzi | E39: DESWIK CHILE SPA | G39: 36610 | I39: 11444638
A40: adig/1189 | B40: 45813 | C40: 2812 | D40: Glosa : Payment: ER - Jorge Moris25.4 - Reimbursable Expense - Vacuna Influenza | 25.4 - Reimbursable Expense - Vacuna Influenza | E40: JORGE MORIS JORDÁN | G40: 19500 | I40: 11464138
A41: adig/1190 | B41: 45813 | C41: 2813 | D41: Glosa : Payment: ER - Caitlin Wheat25.5 - Reimbursable Expense - Reimbursement May 20... | 25.5 - Reimbursable Expense - Reimbursement May 20... | E41: CAITLIN JOY WHEAT | G41: 2300 | I41: 11466438
A42: adig/1191 | B42: 45813 | C42: 2814 | D42: Glosa : Payment: ER - Sebastián Carvallo25.5 - Reimbursable Expense - Lundin Mining - Cand... | 25.5 - Reimbursable Expense - Lundin Mining - Cand... | E42: JUAN CARVALLO JIMÉNEZ | G42: 43000 | I42: 11509438
...

Sheet a sep
A1: Comprobante | B1: Fec. Doc. | C1: Voucher | E1: Titular | F1: T.Doc/Nro | G1: Debe | H1: Haber | I1: Acumulado
A2: adig/1372 | B2: 45876 | C2: 3256 | D2: Glosa : Reembolsos Sebastian Carvallo | E2: JUAN SEBASTIAN CARVALLO JIMÉNEZ | G2: 87720 | I2: -6429422
A3: adig/1373 | B3: 45882 | C3: 3257 | D3: Glosa : MP´s credit card payment | E3: MARCELO PENNA SANTOS | G3: 8406 | I3: -6421016
A4: adig/1374 | B4: 45882 | C4: 3258 | D4: Glosa : Carol's cc payment | E4: CAROL TATIANA CONTRERAS MUÑOZ | G4: 1861875 | I4: -4559141
A5: adig/1375 | B5: 45882 | C5: 3259 | D5: Glosa : Sebastian´s cc payment | E5: JUAN SEBASTIAN CARVALLO JIMÉNEZ | G5: 293855 | I5: -4265286
A6: adig/1376 | B6: 45882 | C6: 3260 | D6: Glosa : KA´s credit card payment | E6: KATHERINNE SILVANA ALARCON ESCOBAR | G6: 1476513 | I6: -2788773
A7: adig/1377 | B7: 45891 | C7: 3264 | D7: Glosa : CM´s credit card payment | E7: CESAR FELIPE MACHADO RIBEIRO LOPES | G7: 2831745 | I7: 42972
A8: adig/1378 | B8: 45891 | C8: 3265 | D8: Glosa : JM´s credit card payment | E8: JORGE MORIS JORDÁN | G8: 44748 | I8: 87720
A9: adig/1551 | B9: 45896 | C9: 3484 | D9: Glosa : TDC CLP/USD CAROl CONTRERAS | E9: CAROL TATIANA CONTRERAS MUÑOZ | H9: 607271 | I9: -519551
A10: adig/1552 | B10: 45896 | C10: 3496 | D10: Glosa : TDC CLP/USD CESAR MACHADO | E10: CESAR FELIPE MACHADO RIBEIRO LOPES | H10: 39966 | I10: -559517
A11: adig/1554 | B11: 45896 | C11: 3506 | D11: Glosa : TDC CLP/USD KATHERINE ALARCON | E11: KATHERINNE SILVANA ALARCON ESCOBAR | H11: 408970 | I11: -968487
A12: adig/1555 | B12: 45896 | C12: 3507 | D12: Glosa : TDC CLP/USD JORGE MORIS | E12: JORGE MORIS JORDÁN | H12: 4257 | I12: -972744
A13: adig/1553 | B13: 45897 | C13: 3504 | D13: Glosa : TDC CLP JUAN sebastian CARVALLO | E13: JUAN SEBASTIAN CARVALLO JIMÉNEZ | H13: 37917 | I13: -1010661
A14: adig/1550 | B14: 45900 | C14: 3483 | D14: Glosa : TDC CLP-USD CAITLIN WHEAT | E14: CAITLIN JOY WHEAT | H14: 965161 | I14: -1975822
A15: adig/1565 | B15: 45904 | C15: 3529 | D15: Glosa : 25.8 - Reimbursable Expense - Reimbursements Augus... | 25.8 - Reimbursable Expense - Reimbursements Augus... | E15: CAITLIN JOY WHEAT | G15: 78080 | I15: -1897742
A16: adig/1597 | B16: 45905 | C16: 3569 | D16: Glosa : 25.8 - Reimbursable Expense - Viaje BHP Assistenci... | E16: DESWIK CHILE SPA | G16: 248681 | I16: -1649061
A17: adig/1566 | B17: 45911 | C17: 3530 | D17: Glosa : 25.9 - Reimbursable Expense - Reimbursement - Empa... | 25.9 - Reimbursable Expense - Reimbursement - Empa... | E17: CAITLIN JOY WHEAT | G17: 67000 | I17: -1582061
A18: adig/1567 | B18: 45911 | C18: 3531 | D18: Glosa : Carol's cc payment | E18: CAROL TATIANA CONTRERAS MUÑOZ | G18: 607270 | I18: -974791
A19: adig/1568 | B19: 45911 | C19: 3532 | D19: Glosa : JM´s credit card payment | E19: JORGE MORIS JORDÁN | G19: 4267 | I19: -970524
A20: adig/1569 | B20: 45911 | C20: 3533 | D20: Glosa : 25.9 - Reimbursable Expense - Reimbursement - Empa... | 25.9 - Reimbursable Expense - Reimbursement - Empa... | E20: CAITLIN JOY WHEAT | G20: 965161 | I20: -5363
A21: adig/1570 | B21: 45911 | C21: 3534 | D21: Glosa : SEBASTIAN CARVALLO | E21: JUAN SEBASTIAN CARVALLO JIMÉNEZ | G21: 37919 | I21: 32556
A22: adig/1571 | B22: 45911 | C22: 3535 | D22: Glosa : Katherinnes credit card payment | E22: KATHERINNE SILVANA ALARCON ESCOBAR | G22: 408970 | I22: 441526
A23: adig/1572 | B23: 45911 | C23: 3536 | D23: Glosa : CM´s credit card payment | E23: CESAR FELIPE MACHADO RIBEIRO LOPES | G23: 36966 | I23: 478492
A24: adig/1599 | B24: 45917 | C24: 3571 | D24: Glosa : Reserva seminario COL | E24: DESWIK CHILE SPA | G24: 1453361 | I24: 1931853
A25: adig/1574 | B25: 45925 | C25: 3538 | D25: Glosa : 25.8 - Reimbursable Expense - Taxi de hotel Atacam... | 25.8 - Reimbursable Expense - Taxi de hotel Atacam... | E25: ANTONIETA GONZALEZ OLIVEROS | G25: 44839 | I25: 1976692
A26: adig/1576 | B26: 45925 | C26: 3540 | D26: Glosa : 25.8 - Reimbursable Expense - Agosto - Implementac... | 25.8 - Reimbursable Expense - Agosto - Implementac... | E26: DESWIK CHILE SPA | G26: 39430 | I26: 2016122
A27: adig/1607 | B27: 45926 | C27: 3579 | D27: Glosa : TDC CLP JUAN sebastian CARVALLO | E27: JUAN SEBASTIAN CARVALLO JIMÉNEZ | H27: 50192 | I27: 1965930
A28: adig/1608 | B28: 45926 | C28: 3580 | D28: Glosa : TDC CLP/USD KATHERINE ALARCON | E28: KATHERINNE SILVANA ALARCON ESCOBAR | H28: 925857 | I28: 1040073
A29: adig/1609 | B29: 45926 | C29: 3581 | D29: Glosa : TDC CLP-USD CAITLIN WHEAT | E29: CAITLIN JOY WHEAT | H29: 943249 | I29: 96824
A30: adig/1610 | B30: 45926 | C30: 3582 | D30: Glosa : TDC CLP/USD CESAR MACHADO | E30: CESAR FELIPE MACHADO RIBEIRO LOPES | H30: 491676 | I30: -394852
D31: Totales:
A32: Totales: | D32: Saldo Final Al 30/09/2025: | G32: 10596806 | H32: 4474516
A33: Saldo Final Al 30/09/2025: | D33: Cuenta: 2114 TARJETAS DE CREDITO USD | I33: -394852
A34: Cuenta: 2114 TARJETAS DE CREDITO USD | D34: Moneda de la Cta: Dólares Americanos
A35: Moneda de la Cta: Dólares Americanos | D35: Comprobante
A36: Comprobante | B36: Fec. Doc. | C36: Voucher | D36: 0 | E36: Titular | F36: T.Doc/Nro | G36: Debe | H36: Haber | I36: Acumulado
A37: adig/1552 | B37: 45896 | C37: 3496 | D37: Glosa : TDC CLP/USD CESAR MACHADO | E37: CESAR FELIPE MACHADO RIBEIRO LOPES | H37: 479.8 | I37: -479.8
A38: adig/1554 | B38: 45896 | C38: 3506 | D38: Glosa : TDC CLP/USD KATHERINE ALARCON | E38: KATHERINNE SILVANA ALARCON ESCOBAR | H38: 487.61 | I38: -967.41
A39: adig/1553 | B39: 45897 | C39: 3504 | D39: Glosa : TDC CLP JUAN sebastian CARVALLO | E39: JUAN SEBASTIAN CARVALLO JIMÉNEZ | H39: 203.9 | I39: -1171.31
A40: adig/1607 | B40: 45926 | C40: 3579 | D40: Glosa : TDC CLP JUAN sebastian CARVALLO | E40: JUAN SEBASTIAN CARVALLO JIMÉNEZ | H40: 239.08 | I40: -1410.39
...

Sheet 9
A1: Comprobante | B1: Fec. Doc. | C1: Voucher | E1: Titular | F1: T.Doc/Nro | G1: Debe | H1: Haber | I1: Acumulado
A2: adig/1122 | B2: 45772 | C2: 2561 | D2: Glosa : TDC CLP-USD CAtherine alaracon | E2: KATHERINNE SILVANA ALARCON ESCOBAR | H2: 806870 | I2: =-H2 -> -806870
A3: adig/1172 | B3: 45792 | C3: 2744 | D3: Glosa : Bank Transfer to CC Katherinne Alarcon. | E3: KATHERINNE SILVANA ALARCON ESCOBAR | G3: 806870 | I3: =+I2+G3 -> 0
A4: adig/1122 | B4: 45772 | C4: 2561 | D4: Glosa : TDC CLP-USD CAtherine alaracon | E4: KATHERINNE SILVANA ALARCON ESCOBAR | H4: 706.36 | I4: =-H4 -> -706.36
A5: adig/1122 | B5: 45772 | C5: 2561 | D5: Glosa : TDC CLP-USD CAtherine alaracon | E5: KATHERINNE SILVANA ALARCON ESCOBAR | G5: 706.36 | I5: =+I4-G5 -> -1412.72
A6: adig/1253 | B6: 45805 | C6: 2909 | D6: Glosa : TDC pesos USD Katherine Alarcon | E6: KATHERINNE SILVANA ALARCON ESCOBAR | H6: 100449 | I6: =-H6 -> -100449
A7: adig/1253 | B7: 45805 | C7: 2909 | D7: Glosa : TDC pesos USD Katherine Alarcon | E7: KATHERINNE SILVANA ALARCON ESCOBAR | H7: 1710.39 | I7: =-H7 -> -1710.39
A8: adig/1203 | B8: 45820 | C8: 2859 | D8: Glosa : Bank Transfer to CC Katherinne Alarcon. | E8: KATHERINNE SILVANA ALARCON ESCOBAR | G8: 100449 | I8: =I6+G8 -> 0
A9: adig/1260 | B9: 45834 | C9: 2916 | D9: Glosa : TDC CLP/USD KATHERINE ALARCON | E9: KATHERINNE SILVANA ALARCON ESCOBAR | G9: 1710.39 | I9: =I7+G9 -> 0
A10: adig/1260 | B10: 45834 | C10: 2916 | D10: Glosa : TDC CLP/USD KATHERINE ALARCON | E10: KATHERINNE SILVANA ALARCON ESCOBAR | H10: 2020460 | I10: =-H10 -> -2020460
A11: adig/1313 | B11: 45848 | C11: 3050 | D11: Glosa : Bank Transfer to CC Katherinne Alarcon. | E11: KATHERINNE SILVANA ALARCON ESCOBAR | G11: 2020460 | I11: =+I10+G11 -> 0
A12: adig/1334 | B12: 45867 | C12: 3093 | D12: Glosa : TDC CLP/USD KATHERINE ALARCON | E12: KATHERINNE SILVANA ALARCON ESCOBAR | H12: 1476513 | I12: =-H12 -> -1476513
A13: adig/1387 | B13: 45869 | C13: 3276 | D13: Glosa : RECLASIFICA TDC K. ALARCON ENERO | E13: KATHERINNE SILVANA ALARCON ESCOBAR | H13: 3388645 | I13: =I12+G13-H13 -> -4865158
A14: adig/1412 | B14: 45869 | C14: 3301 | D14: Glosa : APERTURA TDC K. ALARCON FEB | E14: KATHERINNE SILVANA ALARCON ESCOBAR | H14: 1326542 | I14: =I13+G14-H14 -> -6191700
A15: adig/1417 | B15: 45869 | C15: 3306 | D15: Glosa : APERTURA TDC K. ALARCON MARZO | E15: KATHERINNE SILVANA ALARCON ESCOBAR | H15: 46444 | I15: =I14+G15-H15 -> -6238144
A16: adig/1260 | B16: 45834 | C16: 2916 | D16: Glosa : TDC CLP/USD KATHERINE ALARCON | E16: KATHERINNE SILVANA ALARCON ESCOBAR | H16: 664.62 | I16: =I7+G16-H16 -> -2375.01 | J16: =H16*936.29 -> 622277.06
A17: adig/1334 | B17: 45867 | C17: 3093 | D17: Glosa : TDC CLP/USD KATHERINE ALARCON | E17: KATHERINNE SILVANA ALARCON ESCOBAR | G17: 664.62 | I17: =I9+G17-H17 -> 664.62
G18: =SUM(G2:G17) -> 2930860.4 | H18: =SUM(H2:H17) -> 9169004.4 | I18: =H18-G18 -> 6238144
D21: 2114-09 - CC Katherinne Alarcon | F21: 1476513
B23: Fec. Doc. | C23: Voucher | E23: Titular | G23: Debe | H23: Haber | I23: Acumulado
B24: 45772 | C24: 2561 | D24: Glosa : TDC CLP-USD CAtherine alaracon | E24: KATHERINNE SILVANA ALARCON ESCOBAR | H24: 806870 | I24: -4472434
B25: 45785 | C25: 2723 | D25: Glosa : Payment: ER - Katherinne Alarcon25.3 - Reimbursable Expense - Viaje Lima | 25.3 - Reimbursable Expense - Viaje Lima | E25: KATHERINNE SILVANA ALARCON ESCOBAR | G25: 15336 | I25: -4439332
B26: 45792 | C26: 2744 | D26: Glosa : Bank Transfer to CC Katherinne Alarcon. | E26: KATHERINNE SILVANA ALARCON ESCOBAR | G26: 806870 | I26: -461997
B27: 45805 | C27: 2909 | D27: Glosa : TDC pesos USD Katherine Alarcon | E27: KATHERINNE SILVANA ALARCON ESCOBAR | H27: 100449 | I27: -337221
B28: 45820 | C28: 2859 | D28: Glosa : Bank Transfer to CC Katherinne Alarcon. | E28: KATHERINNE SILVANA ALARCON ESCOBAR | G28: 100449 | I28: -185685
B29: 45834 | C29: 2916 | D29: Glosa : TDC CLP/USD KATHERINE ALARCON | E29: KATHERINNE SILVANA ALARCON ESCOBAR | H29: 2020460 | I29: -3592848
B30: 45848 | C30: 3050 | D30: Glosa : Bank Transfer to CC Katherinne Alarcon. | E30: KATHERINNE SILVANA ALARCON ESCOBAR | G30: 2020460 | I30: -524788
B31: 45867 | C31: 3093 | D31: Glosa : TDC CLP/USD KATHERINE ALARCON | E31: KATHERINNE SILVANA ALARCON ESCOBAR | H31: 1476513 | I31: -3755343
B32: 45869 | C32: 3276 | D32: Glosa : RECLASIFICA TDC K. ALARCON ENERO | E32: KATHERINNE SILVANA ALARCON ESCOBAR | H32: 3388645 | I32: -14255289
B33: 45869 | C33: 3301 | D33: Glosa : APERTURA TDC K. ALARCON FEB | E33: KATHERINNE SILVANA ALARCON ESCOBAR | H33: 1326542 | I33: -20889556 | J33: 2011
B34: 45869 | C34: 3306 | D34: Glosa : APERTURA TDC K. ALARCON MARZO | E34: KATHERINNE SILVANA ALARCON ESCOBAR | H34: 46444 | I34: -22199356
B35: 45869 | C35: 3451 | D35: Glosa : reclasifica CC Expense | E35: KATHERINNE SILVANA ALARCON ESCOBAR | H35: 15336 | I35: -24836047
B37: Fec. Doc. | C37: Voucher | E37: Titular | F37: T.Doc/Nro | G37: Debe | H37: Haber | I37: Acumulado
B38: 45772 | C38: 2561 | D38: Glosa : TDC CLP-USD CAtherine alaracon | E38: KATHERINNE SILVANA ALARCON ESCOBAR | H38: 806870 | I38: =-H38 -> -806870
B39: 45785 | C39: 2723 | D39: Glosa : Payment: ER - Katherinne Alarcon25.3 - Reimbursable Expense - Viaje Lima | 25.3 - Reimbursable Expense - Viaje Lima | E39: KATHERINNE SILVANA ALARCON ESCOBAR | G39: 15336 | I39: =I38+G39-H39 -> -791534
B40: 45792 | C40: 2744 | D40: Glosa : Bank Transfer to CC Katherinne Alarcon. | E40: KATHERINNE SILVANA ALARCON ESCOBAR | G40: 806870 | I40: =I39+G40-H40 -> 15336
B41: 45805 | C41: 2909 | D41: Glosa : TDC pesos USD Katherine Alarcon | E41: KATHERINNE SILVANA ALARCON ESCOBAR | H41: 100449 | I41: =I40+G41-H41 -> -85113
B42: 45820 | C42: 2859 | D42: Glosa : Bank Transfer to CC Katherinne Alarcon. | E42: KATHERINNE SILVANA ALARCON ESCOBAR | G42: 100449 | I42: =I41+G42-H42 -> 15336
B43: 45834 | C43: 2916 | D43: Glosa : TDC CLP/USD KATHERINE ALARCON | E43: KATHERINNE SILVANA ALARCON ESCOBAR | H43: 2020460 | I43: =I42+G43-H43 -> -2005124
B44: 45848 | C44: 3050 | D44: Glosa : Bank Transfer to CC Katherinne Alarcon. | E44: KATHERINNE SILVANA ALARCON ESCOBAR | G44: 2020460 | I44: =I43+G44-H44 -> 15336
...

Sheet 9_x
A1: Account Code | B1: Account | C1: Date | D1: Source | E1: Description | F1: Reference | G1: Debit | H1: Credit
A2: 2114-09 | B2: CC Katherinne Alarcon | C2: 45667 | D2: Spend Money | E2: CC Expense | F2: Dinner and drinks | G2: 0 | H2: 350570 | I2: =+G2-H2 -> -350570
A3: 2114-09 | B3: CC Katherinne Alarcon | C3: 45667 | D3: Spend Money | E3: CC Expense | F3: Dinner and drinks | G3: 0 | H3: 51920 | I3: =I2+G3-H3 -> -402490
A4: 2114-09 | B4: CC Katherinne Alarcon | C4: 45670 | D4: Bank Transfer | E4: Bank Transfer from Citibank - CLP to CC Katherinne Alarcon | F4: CC Automatic Payment | G4: 2919571 | H4: 0 | I4: =I3+G4-H4 -> 2517081
A5: 2114-09 | B5: CC Katherinne Alarcon | C5: 45670 | D5: Spend Money | E5: Banco De Chile | G5: 0 | H5: 697 | I5: =I4+G5-H5 -> 2516384
A6: 2114-09 | B6: CC Katherinne Alarcon | C6: 45673 | D6: Payable Payment | E6: Payment: LATAM | F6: F/6268133 | G6: 0 | H6: 110880 | I6: =I5+G6-H6 -> 2405504
A7: 2114-09 | B7: CC Katherinne Alarcon | C7: 45675 | D7: Spend Money | E7: CC Expense | F7: Taxi aeropuerto domicilio | G7: 0 | H7: 26000 | I7: =I6+G7-H7 -> 2379504
A8: 2114-09 | B8: CC Katherinne Alarcon | C8: 45675 | D8: Spend Money | E8: CC Expense | F8: Snack Aeropuerto | G8: 0 | H8: 5681.58 | I8: =I7+G8-H8 -> 2373822.4
A9: 2114-09 | B9: CC Katherinne Alarcon | C9: 45675 | D9: Spend Money | E9: CC Expense | F9: Cafe aeropuerto | G9: 0 | H9: 6877.18 | I9: =I8+G9-H9 -> 2366945.2
A10: 2114-09 | B10: CC Katherinne Alarcon | C10: 45677 | D10: Spend Money | E10: Banco De Chile | G10: 0 | H10: 889 | I10: =I9+G10-H10 -> 2366056.2
A11: 2114-09 | B11: CC Katherinne Alarcon | C11: 45677 | D11: Spend Money | E11: Banco De Chile | G11: 0 | H11: 141 | I11: =I10+G11-H11 -> 2365915.2
A12: 2114-09 | B12: CC Katherinne Alarcon | C12: 45677 | D12: Spend Money | E12: Banco De Chile | G12: 0 | H12: 172 | I12: =I11+G12-H12 -> 2365743.2
A13: 2114-09 | B13: CC Katherinne Alarcon | C13: 45681 | D13: Adjustment | E13: Reconciliation adjustment | G13: 0 | H13: 0.01 | I13: =I12+G13-H13 -> 2365743.2
A14: 2114-09 | B14: CC Katherinne Alarcon | C14: 45681 | D14: Payable Payment | E14: Payment: LATAM | F14: F/6281525 | G14: 0 | H14: 814728 | I14: =I13+G14-H14 -> 1551015.2
A15: 2114-09 | B15: CC Katherinne Alarcon | C15: 45681 | D15: Payable Payment | E15: Payment: LATAM | F15: F/6282508 | G15: 0 | H15: 96556 | I15: =I14+G15-H15 -> 1454459.2
A16: 2114-09 | B16: CC Katherinne Alarcon | C16: 45686 | D16: Spend Money | E16: Banco De Chile | G16: 0 | H16: 3839 | I16: =I15+G16-H16 -> 1450620.2
A17: 2114-09 | B17: CC Katherinne Alarcon | C17: 45687 | D17: Spend Money | E17: CC Expense | F17: Taxi aeropuerto Hotel | G17: 0 | H17: 27311.08 | I17: =I16+G17-H17 -> 1423309.1
A18: 2114-09 | B18: CC Katherinne Alarcon | C18: 45687 | D18: Spend Money | E18: CC Expense | F18: Cenas | G18: 0 | H18: 34870.05 | I18: =I17+G18-H18 -> 1388439.1
A19: 2114-09 | B19: CC Katherinne Alarcon | C19: 45688 | D19: Spend Money | E19: CC Expense | F19: Patente comercial | G19: 0 | H19: 1520151 | I19: =I18+G19-H19 -> -131711.9
A20: 2114-09 | B20: CC Katherinne Alarcon | C20: 45688 | D20: Spend Money | E20: CC Expense | F20: Pasaje Sebastian | G20: 0 | H20: 399065 | I20: =I19+G20-H20 -> -530776.9
A21: 2114-09 | B21: CC Katherinne Alarcon | C21: 45690 | D21: Spend Money | E21: CC Expense | F21: Dif pasjae Katherinne BH | G21: 0 | H21: 13036.99 | I21: =I20+G21-H21 -> -543813.89
A22: 2114-09 | B22: CC Katherinne Alarcon | C22: 45692 | D22: Spend Money | E22: CC Expense | F22: Almuerzo con el equipo | G22: 0 | H22: 667150 | I22: =I21+G22-H22 -> -1210963.9
A23: 2114-09 | B23: CC Katherinne Alarcon | C23: 45693 | D23: Bank Transfer | E23: Bank Transfer from Citibank - CLP to CC Katherinne Alarcon | F23: KA CC payment | G23: 1611355 | H23: 0 | I23: =I22+G23-H23 -> 400391.11
A24: 2114-09 | B24: CC Katherinne Alarcon | C24: 45693 | D24: Spend Money | E24: CC Expense | F24: Cena con Equipo | G24: 0 | H24: 355520 | I24: =I23+G24-H24 -> 44871.11
A25: 2114-09 | B25: CC Katherinne Alarcon | C25: 45693 | D25: Spend Money | E25: CC Expense | F25: Almuerzo | G25: 0 | H25: 64779 | I25: =I24+G25-H25 -> -19907.89
A26: 2114-09 | B26: CC Katherinne Alarcon | C26: 45694 | D26: Spend Money | E26: CC Expense | F26: Almuerzo | G26: 0 | H26: 11950 | I26: =I25+G26-H26 -> -31857.89
A27: 2114-09 | B27: CC Katherinne Alarcon | C27: 45694 | D27: Spend Money | E27: CC Expense | F27: almuerzo | G27: 0 | H27: 53207 | I27: =I26+G27-H27 -> -85064.89
A28: 2114-09 | B28: CC Katherinne Alarcon | C28: 45701 | D28: Bank Transfer | E28: Bank Transfer from Citibank - CLP to CC Katherinne Alarcon | F28: CC payment Katherinne | G28: 1777290 | H28: 0 | I28: =I27+G28-H28 -> 1692225.1
A29: 2114-09 | B29: CC Katherinne Alarcon | C29: 45713 | D29: Payable Payment | E29: Payment: PROD - RED DE TRANSPORTES COMERCIALES LTDA | F29: F/62420 | G29: 0 | H29: 71240 | I29: =I28+G29-H29 -> 1620985.1
A30: 2114-09 | B30: CC Katherinne Alarcon | C30: 45714 | D30: Spend Money | E30: Banco De Chile | G30: 0 | H30: 49 | I30: =I29+G30-H30 -> 1620936.1
A31: 2114-09 | B31: CC Katherinne Alarcon | C31: 45714 | D31: Spend Money | E31: Banco De Chile | G31: 0 | H31: 3862 | I31: =I30+G31-H31 -> 1617074.1
A32: 2114-09 | B32: CC Katherinne Alarcon | C32: 45714 | D32: Spend Money | E32: Banco De Chile | G32: 0 | H32: 1835 | I32: =I31+G32-H32 -> 1615239.1
A33: 2114-09 | B33: CC Katherinne Alarcon | C33: 45715 | D33: Spend Money | E33: CC Expense | F33: Fruta semana 24 feb | G33: 0 | H33: 23352 | I33: =I32+G33-H33 -> 1591887.1
A34: 2114-09 | B34: CC Katherinne Alarcon | C34: 45716 | D34: Receive Money | E34: Banco De Chile | G34: 1141.89 | H34: 0 | I34: =I33+G34-H34 -> 1593029
A35: 2114-09 | B35: CC Katherinne Alarcon | C35: 45723 | D35: Bank Transfer | E35: Bank Transfer from Citibank - CLP to CC Katherinne Alarcon | F35: Katherinne A CC payment | G35: 1326542 | H35: 0 | I35: =I34+G35-H35 -> 2919571
A36: 2114-09 | B36: CC Katherinne Alarcon | C36: 45732 | D36: Spend Money | E36: Provision Expenses CC | G36: 0 | H36: 22214 | I36: =I35+G36-H36 -> 2897357
A37: 2114-09 | B37: CC Katherinne Alarcon | C37: 45733 | D37: Spend Money | E37: Provision Expenses CC | G37: 0 | H37: 8354 | I37: =I36+G37-H37 -> 2889003
A38: 2114-09 | B38: CC Katherinne Alarcon | C38: 45733 | D38: Spend Money | E38: Provision Expenses CC | G38: 0 | H38: 110552 | I38: =I37+G38-H38 -> 2778451
A39: 2114-09 | B39: CC Katherinne Alarcon | C39: 45734 | D39: Spend Money | E39: Banco De Chile | G39: 0 | H39: 553 | I39: =I38+G39-H39 -> 2777898
A40: 2114-09 | B40: CC Katherinne Alarcon | C40: 45734 | D40: Spend Money | E40: Banco De Chile | G40: 0 | H40: 206 | I40: =I39+G40-H40 -> 2777692
...

Sheet 10
A1: Comprobante | B1: Fec. Doc. | C1: Voucher | E1: Titular | F1: T.Doc/Nro | G1: Debe | H1: Haber | I1: Acumulado
A2: adig/1114 | B2: 45772 | C2: 2553 | D2: Glosa : TDC CLP_USD C.Contreras | E2: CAROL TATIANA CONTRERAS MUÑOZ | H2: 3070443 | I2: =-H2 -> -3070443
A3: adig/1171 | B3: 45792 | C3: 2743 | D3: Glosa : Bank Transfer to CC Carol Contreras. | E3: CAROL TATIANA CONTRERAS MUÑOZ | G3: 3070443 | I3: =+I2+G3 -> 0
A4: adig/1251 | B4: 45805 | C4: 2907 | D4: Glosa : TDC CLP_USD C.Contreras | E4: CAROL TATIANA CONTRERAS MUÑOZ | H4: 1231423 | I4: =-H4 -> -1231423
A5: adig/1207 | B5: 45820 | C5: 2863 | D5: Glosa : Bank Transfer to CC Carol Contreras. | E5: CAROL TATIANA CONTRERAS MUÑOZ | G5: 1231423 | I5: =+I4+G5 -> 0
A6: adig/1256 | B6: 45834 | C6: 2912 | D6: Glosa : TDC CLP/USD CARLO CONTRERAS | E6: CAROL TATIANA CONTRERAS MUÑOZ | H6: 981428 | I6: =-H6 -> -981428
A7: adig/1312 | B7: 45848 | C7: 3049 | D7: Glosa : Bank Transfer to CC Carol Contreras. | E7: CAROL TATIANA CONTRERAS MUÑOZ | G7: 981428 | I7: =+I6+G7 -> 0
A8: adig/1311 | B8: 45845 | C8: 3041 | D8: Glosa : Payment: ER - Carol Contreras 25.7 - Reimbursable Expense - compra cervezas happ... | 25.7 - Reimbursable Expense - compra cervezas happ... | E8: CAROL TATIANA CONTRERAS MUÑOZ | G8: 33059 | I8: =+G8 -> 33059
A9: adig/1333 | B9: 45867 | C9: 3092 | D9: Glosa : TDC CLP/USD CAROl CONTRERAS | E9: CAROL TATIANA CONTRERAS MUÑOZ | H9: 1861875 | I9: =-H9 -> -1861875
A10: adig/1382 | B10: 45869 | C10: 3271 | D10: Glosa : RECLASIFICA GASTOS RENDICION Carol contreras | E10: CAROL TATIANA CONTRERAS MUÑOZ | H10: 1913232 | I10: =-H10 -> -1913232
A11: adig/1383 | B11: 45869 | C11: 3272 | D11: Glosa : RECLASIFICA GASTOS RENDICION Carol contreras feb | E11: CAROL TATIANA CONTRERAS MUÑOZ | H11: 2328147 | I11: =-H11 -> -2328147
A12: adig/1384 | B12: 45869 | C12: 3273 | D12: Glosa : RECLASIFICA GASTOS RENDICION Carol contreras mar | E12: CAROL TATIANA CONTRERAS MUÑOZ | H12: 1497172 | I12: =-H12 -> -1497172
A15: adig/1114 | B15: 45772 | C15: 2553 | D15: Glosa : TDC CLP_USD C.Contreras | E15: CONTRERAS | G15: 975.05 | I15: 975.05
A16: adig/1114 | B16: 45772 | C16: 2553 | D16: Glosa : TDC CLP_USD C.Contreras | E16: CONTRERAS | H16: 975.05 | I16: 0
D19: 2114-10 - CC Carol Contreras | F19: 1861875
B22: Fec. Doc. | C22: Voucher | E22: Titular | G22: Debe | H22: Haber | I22: Acumulado
B23: 45772 | C23: 2553 | D23: Glosa : TDC CLP_USD C.Contreras | E23: CAROL TATIANA CONTRERAS MUÑOZ | H23: 3070443 | I23: -2948765
B24: 45792 | C24: 2743 | D24: Glosa : Bank Transfer to CC Carol Contreras. | E24: CAROL TATIANA CONTRERAS MUÑOZ | G24: 3070443 | I24: -1268867
B25: 45805 | C25: 2907 | D25: Glosa : TDC CLP_USD C.Contreras | E25: CAROL TATIANA CONTRERAS MUÑOZ | H25: 1231423 | I25: -165685
B26: 45820 | C26: 2863 | D26: Glosa : Bank Transfer to CC Carol Contreras. | E26: CAROL TATIANA CONTRERAS MUÑOZ | G26: 1231423 | I26: 1406242
B27: 45834 | C27: 2912 | D27: Glosa : TDC CLP/USD CARLO CONTRERAS | E27: CAROL TATIANA CONTRERAS MUÑOZ | H27: 981428 | I27: 433814
B28: 45845 | C28: 3041 | D28: Glosa : Payment: ER - Carol Contreras 25.7 - Reimbursable Expense - compra cervezas happ... | 25.7 - Reimbursable Expense - compra cervezas happ... | E28: CAROL TATIANA CONTRERAS MUÑOZ | G28: 33059 | I28: -3526676
B29: 45848 | C29: 3049 | D29: Glosa : Bank Transfer to CC Carol Contreras. | E29: CAROL TATIANA CONTRERAS MUÑOZ | G29: 981428 | I29: -2545248
B30: 45867 | C30: 3092 | D30: Glosa : TDC CLP/USD CAROl CONTRERAS | E30: CAROL TATIANA CONTRERAS MUÑOZ | H30: 1861875 | I30: -2278830
B31: 45869 | C31: 3271 | D31: Glosa : RECLASIFICA GASTOS RENDICION Carol contreras | E31: CAROL TATIANA CONTRERAS MUÑOZ | H31: 1913232 | I31: -6780412 | J31: 2011
B32: 45869 | C32: 3272 | D32: Glosa : RECLASIFICA GASTOS RENDICION Carol contreras feb | E32: CAROL TATIANA CONTRERAS MUÑOZ | H32: 2328147 | I32: -9108559 | J32: 2011
B33: 45869 | C33: 3273 | D33: Glosa : RECLASIFICA GASTOS RENDICION Carol contreras mar | E33: CAROL TATIANA CONTRERAS MUÑOZ | H33: 1497172 | I33: -10605731
B34: 45869 | C34: 3458 | D34: Glosa : Spend Money CC Expense ABRIL-MAYO-JUNIO-JULIO | E34: CAROL TATIANA CONTRERAS MUÑOZ | H34: 460158 | I34: -25653462 | J34: ?
B35: 45869 | C35: 3458 | D35: Glosa : Spend Money CC Expense ABRIL-MAYO-JUNIO-JULIO | E35: CAROL TATIANA CONTRERAS MUÑOZ | H35: 100167 | I35: -25753629 | J35: ?
B36: 45869 | C36: 3458 | D36: Glosa : Spend Money CC Expense ABRIL-MAYO-JUNIO-JULIO | E36: CAROL TATIANA CONTRERAS MUÑOZ | H36: 289020 | I36: -26042649 | J36: ?
B37: 45869 | C37: 3458 | D37: Glosa : Spend Money CC Expense ABRIL-MAYO-JUNIO-JULIO | E37: CAROL TATIANA CONTRERAS MUÑOZ | H37: 356370 | I37: -26399019 | J37: ?
B40: Fec. Doc. | C40: Voucher | E40: Titular | F40: T.Doc/Nro | G40: Debe | H40: Haber | I40: Acumulado
B41: 45772 | C41: 2553 | D41: Glosa : TDC CLP_USD C.Contreras | E41: CAROL TATIANA CONTRERAS MUÑOZ | H41: 3070443 | I41: =-H41 -> -3070443
B42: 45792 | C42: 2743 | D42: Glosa : Bank Transfer to CC Carol Contreras. | E42: CAROL TATIANA CONTRERAS MUÑOZ | G42: 3070443 | I42: =I41+G42-H42 -> 0
B43: 45805 | C43: 2907 | D43: Glosa : TDC CLP_USD C.Contreras | E43: CAROL TATIANA CONTRERAS MUÑOZ | H43: 1231423 | I43: =I42+G43-H43 -> -1231423
B44: 45820 | C44: 2863 | D44: Glosa : Bank Transfer to CC Carol Contreras. | E44: CAROL TATIANA CONTRERAS MUÑOZ | G44: 1231423 | I44: =I43+G44-H44 -> 0
B45: 45834 | C45: 2912 | D45: Glosa : TDC CLP/USD CARLO CONTRERAS | E45: CAROL TATIANA CONTRERAS MUÑOZ | H45: 981428 | I45: =I44+G45-H45 -> -981428
B46: 45845 | C46: 3041 | D46: Glosa : Payment: ER - Carol Contreras 25.7 - Reimbursable Expense - compra cervezas happ... | 25.7 - Reimbursable Expense - compra cervezas happ... | E46: CAROL TATIANA CONTRERAS MUÑOZ | G46: 33059 | I46: =I45+G46-H46 -> -948369
B47: 45848 | C47: 3049 | D47: Glosa : Bank Transfer to CC Carol Contreras. | E47: CAROL TATIANA CONTRERAS MUÑOZ | G47: 981428 | I47: =I46+G47-H47 -> 33059
B48: 45867 | C48: 3092 | D48: Glosa : TDC CLP/USD CAROl CONTRERAS | E48: CAROL TATIANA CONTRERAS MUÑOZ | H48: 1861875 | I48: =I47+G48-H48 -> -1828816
...

Sheet 10_X
A1: Account Code | B1: Account | C1: Date | D1: Source | E1: Description | F1: Reference | G1: Debit | H1: Credit
A2: 2114-10 | B2: CC Carol Contreras | C2: 45659 | D2: Payable Payment | E2: Payment: PROD - RED DE TRANSPORTES COMERCIALES LTDA | F2: F/60232 | G2: 0 | H2: 156090 | I2: =+G2-H2 -> -156090
A3: 2114-10 | B3: CC Carol Contreras | C3: 45663 | D3: Payable Payment | E3: Payment: Telefonica Chile S.A (Movistar) | F3: F/52229965 | G3: 0 | H3: 294887 | I3: =I2+G3-H3 -> -450977
A4: 2114-10 | B4: CC Carol Contreras | C4: 45663 | D4: Payable Payment | E4: Payment: Telefonica Chile S.A (Movistar) | F4: F/50708669 | G4: 0 | H4: 24003 | I4: =I3+G4-H4 -> -474980
A5: 2114-10 | B5: CC Carol Contreras | C5: 45664 | D5: Spend Money | E5: CC Expense | F5: tortas cumpleaos la danesa | G5: 0 | H5: 83390 | I5: =I4+G5-H5 -> -558370
A6: 2114-10 | B6: CC Carol Contreras | C6: 45664 | D6: Payable Payment | E6: Payment: BECKER PADRUNO GRATTINI Y COMPANIA LTDA | F6: 1044458 | G6: 0 | H6: 208720 | I6: =I5+G6-H6 -> -767090
A7: 2114-10 | B7: CC Carol Contreras | C7: 45666 | D7: Spend Money | E7: CC Expense | F7: almuerzo oficina Black Chiken | G7: 0 | H7: 162830 | I7: =I6+G7-H7 -> -929920
A8: 2114-10 | B8: CC Carol Contreras | C8: 45666 | D8: Spend Money | E8: CC Expense | F8: black Chiken happy hour cesar | G8: 0 | H8: 15980 | I8: =I7+G8-H8 -> -945900
A9: 2114-10 | B9: CC Carol Contreras | C9: 45666 | D9: Spend Money | E9: CC Expense | F9: OXXO happy Hour cesar | G9: 0 | H9: 4380 | I9: =I8+G9-H9 -> -950280
A10: 2114-10 | B10: CC Carol Contreras | C10: 45667 | D10: Spend Money | E10: CC Expense | F10: uber happy hour cesar marcelo | G10: 0 | H10: 22008 | I10: =I9+G10-H10 -> -972288
A11: 2114-10 | B11: CC Carol Contreras | C11: 45667 | D11: Spend Money | E11: CC Expense | F11: choripanes cesar unimarc | G11: 0 | H11: 53148 | I11: =I10+G11-H11 -> -1025436
A12: 2114-10 | B12: CC Carol Contreras | C12: 45670 | D12: Bank Transfer | E12: Bank Transfer from Citibank - CLP to CC Carol Contreras | F12: CC Automatic Payment | G12: 949710 | H12: 0 | I12: =I11+G12-H12 -> -75726
A13: 2114-10 | B13: CC Carol Contreras | C13: 45670 | D13: Spend Money | E13: CC Expense | F13: torta cumpleaos carol | G13: 0 | H13: 29000 | I13: =I12+G13-H13 -> -104726
A14: 2114-10 | B14: CC Carol Contreras | C14: 45670 | D14: Spend Money | E14: CC Expense | F14: uber dennisse cena Cesar y andrew | G14: 0 | H14: 11889 | I14: =I13+G14-H14 -> -116615
... A19: 2114-10 | B19: CC Carol Contreras | C19: 45678 | D19: Spend Money | E19: CC Expense | F19: fruta oficina | G19: 0 | H19: 24120 | I19: =I18+G19-H19 -> -901954
A20: 2114-10 | B20: CC Carol Contreras | C20: 45678 | D20: Spend Money | E20: uber | G20: 1206 | H20: 0 | I20: =I19+G20-H20 -> -900748
A21: 2114-10 | B21: CC Carol Contreras | C21: 45678 | D21: Spend Money | E21: uber | G21: 0 | H21: 1206 | I21: =I20+G21-H21 -> -901954
A22: 2114-10 | B22: CC Carol Contreras | C22: 45684 | D22: Spend Money | E22: CC Expense | F22: fruta oficina | G22: 0 | H22: 21759 | I22: =I21+G22-H22 -> -923713
A23: 2114-10 | B23: CC Carol Contreras | C23: 45684 | D23: Spend Money | E23: CC Expense | F23: audifonos carol | G23: 0 | H23: 9990 | I23: =I22+G23-H23 -> -933703
A24: 2114-10 | B24: CC Carol Contreras | C24: 45684 | D24: Spend Money | E24: uber | G24: 0 | H24: 1036 | I24: =I23+G24-H24 -> -934739
A25: 2114-10 | B25: CC Carol Contreras | C25: 45684 | D25: Spend Money | E25: uber | G25: 1036 | H25: 0 | I25: =I24+G25-H25 -> -933703
A26: 2114-10 | B26: CC Carol Contreras | C26: 45686 | D26: Spend Money | E26: Banco De Chile | G26: 0 | H26: 3839 | I26: =I25+G26-H26 -> -937542
A27: 2114-10 | B27: CC Carol Contreras | C27: 45687 | D27: Payable Payment | E27: Payment: CVH STORE SPA | F27: F/1604 | G27: 0 | H27: 53980 | I27: =I26+G27-H27 -> -991522
A28: 2114-10 | B28: CC Carol Contreras | C28: 45689 | D28: Spend Money | E28: CC Expense | F28: uber despedida Marcelo Siro | G28: 0 | H28: 7420 | I28: =I27+G28-H28 -> -998942
A29: 2114-10 | B29: CC Carol Contreras | C29: 45689 | D29: Spend Money | E29: CC Expense | F29: uber denisse despedida Marcelo siro | G29: 0 | H29: 12546 | I29: =I28+G29-H29 -> -1011488
A30: 2114-10 | B30: CC Carol Contreras | C30: 45689 | D30: Spend Money | E30: CC Expense | F30: uber carol despedida marcelo siro | G30: 0 | H30: 10361 | I30: =I29+G30-H30 -> -1021849
A31: 2114-10 | B31: CC Carol Contreras | C31: 45689 | D31: Adjustment | E31: Reconciliation adjustment | G31: 20 | H31: 0 | I31: =I30+G31-H31 -> -1021829
A32: 2114-10 | B32: CC Carol Contreras | C32: 45691 | D32: Spend Money | E32: CC Expense | F32: almuerzo staff Brazil | G32: 0 | H32: 109395 | I32: =I31+G32-H32 -> -1131224
A33: 2114-10 | B33: CC Carol Contreras | C33: 45691 | D33: Spend Money | E33: CC Expense | F33: uber fruta oficina | G33: 0 | H33: 23607 | I33: =I32+G33-H33 -> -1154831
A34: 2114-10 | B34: CC Carol Contreras | C34: 45691 | D34: Spend Money | E34: CC Expense | F34: Cambio de pasaje francisco Balmaceda | G34: 0 | H34: 6600 | I34: =I33+G34-H34 -> -1161431
A35: 2114-10 | B35: CC Carol Contreras | C35: 45691 | D35: Spend Money | E35: CC Expense | F35: uber tramites bancarios | G35: 0 | H35: 4333 | I35: =I34+G35-H35 -> -1165764
A36: 2114-10 | B36: CC Carol Contreras | C36: 45691 | D36: Spend Money | E36: CC Expense | F36: uber tramites Bancarios | G36: 0 | H36: 3911 | I36: =I35+G36-H36 -> -1169675
A37: 2114-10 | B37: CC Carol Contreras | C37: 45691 | D37: Payable Payment | E37: Payment: PROD - RED DE TRANSPORTES COMERCIALES LTDA | F37: F/61615 | G37: 0 | H37: 113249 | I37: =I36+G37-H37 -> -1282924
A38: 2114-10 | B38: CC Carol Contreras | C38: 45691 | D38: Payable Payment | E38: Payment: PRODUCOTS TECNOLOGICOS B&V SPA | F38: F/6379 | G38: 0 | H38: 22990 | I38: =I37+G38-H38 -> -1305914
A39: 2114-10 | B39: CC Carol Contreras | C39: 45691 | D39: Adjustment | E39: Reconciliation adjustment | G39: 0 | H39: 1 | I39: =I38+G39-H39 -> -1305915
A40: 2114-10 | B40: CC Carol Contreras | C40: 45692 | D40: Spend Money | E40: CC Expense | F40: franui oficina | G40: 0 | H40: 27730 | I40: =I39+G40-H40 -> -1333645
A41: 2114-10 | B41: CC Carol Contreras | C41: 45693 | D41: Bank Transfer | E41: Bank Transfer from Citibank - CLP to CC Carol Contreras | F41: Carol CC payment | G41: 1994192 | H41: 0 | I41: =I40+G41-H41 -> 660547
A42: 2114-10 | B42: CC Carol Contreras | C42: 45693 | D42: Payable Payment | E42: Payment: INVERSIONES Y ASESORIAS RA SPA | F42: F/325 | G42: 0 | H42: 26980 | I42: =I41+G42-H42 -> 633567
A43: 2114-10 | B43: CC Carol Contreras | C43: 45694 | D43: Payable Payment | E43: Payment: Telefonica Chile S.A (Movistar) | F43: F/52597895 | G43: 0 | H43: 294600 | I43: =I42+G43-H43 -> 338967
A44: 2114-10 | B44: CC Carol Contreras | C44: 45694 | D44: Payable Payment | E44: Payment: LATAM AIRLINES GROUP SA | F44: F/6302257 | G44: 0 | H44: 152842 | I44: =I43+G44-H44 -> 186125
...

Sheet 11
A1: Comprobante | B1: Fec. Doc. | C1: Voucher | E1: Titular | F1: T.Doc/Nro | G1: Debe | H1: Haber | I1: Acumulado
A2: adig/1116 | B2: 45772 | C2: 2555 | D2: Glosa : TDC CLP JUAN CARVALLO | E2: JUAN CARVALLO JIMÉNEZ | H2: 122074 | I2: -3687220
A3: adig/1174 | B3: 45792 | C3: 2746 | D3: Glosa : Bank Transfer to CC Sebastián Carvallo. | E3: JUAN CARVALLO JIMÉNEZ | G3: 72314 | I3: -544463
A4: adig/1255 | B4: 45805 | C4: 2911 | D4: Glosa : TDC CLP JUAN sebastian CARVALLO | E4: JUAN CARVALLO JIMÉNEZ | H4: 161109 | I4: -498439
A5: adig/1553 | B5: 45805 | C5: 3504 | D5: Glosa : TDC CLP JUAN sebastian CARVALLO | E5: JUAN CARVALLO JIMÉNEZ | H5: 229285 | I5: -779243
A6: adig/1206 | B6: 45820 | C6: 2862 | D6: Glosa : Bank Transfer to CC Sebastián Carvallo. | E6: JUAN CARVALLO JIMÉNEZ | G6: 210396 | I6: 107093
A7: adig/1335 | B7: 45867 | C7: 3094 | D7: Glosa : TDC CLP JUAN sebastian CARVALLO | E7: JUAN CARVALLO JIMÉNEZ | H7: 293855 | I7: -3600643
A8: adig/1397 | B8: 45869 | C8: 3286 | D8: Glosa : APERTURA TDC J. SEBASTIAN C. ENERO | E8: JUAN CARVALLO JIMÉNEZ | H8: 650343 | I8: -13820934
A9: adig/1414 | B9: 45869 | C9: 3303 | D9: Glosa : APERTURA TDC JS. CARVALLO FEB | E9: JUAN CARVALLO JIMÉNEZ | H9: 20962 | I9: -20359392
D12: 2114-11 - CC Sebastián Carvallo | G12: 293855
B14: Fec. Doc. | C14: Voucher | E14: Titular | G14: Debe | H14: Haber | I14: Acumulado
B15: 45772 | C15: 2555 | D15: Glosa : TDC CLP JUAN CARVALLO | E15: JUAN CARVALLO JIMÉNEZ | H15: 122074 | I15: =-H15 -> -122074
B16: 45792 | C16: 2746 | D16: Glosa : Bank Transfer to CC Sebastián Carvallo. | E16: JUAN CARVALLO JIMÉNEZ | G16: 72314 | I16: =I15+G16-H16 -> -49760
B17: 45805 | C17: 2911 | D17: Glosa : TDC CLP JUAN sebastian CARVALLO | E17: JUAN CARVALLO JIMÉNEZ | H17: 161109 | I17: =I16+G17-H17 -> -210869
B18: 45805 | C18: 3504 | D18: Glosa : TDC CLP JUAN sebastian CARVALLO | E18: JUAN CARVALLO JIMÉNEZ | H18: 229285 | I18: =I17+G18-H18 -> -440154
B19: 45813 | C19: 2814 | D19: Glosa : Payment: ER - Sebastián Carvallo25.5 - Reimbursable Expense - Lundin Mining - Cand... | 25.5 - Reimbursable Expense - Lundin Mining - Cand... | E19: JUAN CARVALLO JIMÉNEZ | G19: 43000 | I19: =I18+G19-H19 -> -397154
B20: 45820 | C20: 2862 | D20: Glosa : Bank Transfer to CC Sebastián Carvallo. | E20: JUAN CARVALLO JIMÉNEZ | G20: 210396 | I20: =I19+G20-H20 -> -186758
B21: 45867 | C21: 3094 | D21: Glosa : TDC CLP JUAN sebastian CARVALLO | E21: JUAN CARVALLO JIMÉNEZ | H21: 293855 | I21: -4049198
B22: 45869 | C22: 3286 | D22: Glosa : APERTURA TDC J. SEBASTIAN C. ENERO | E22: JUAN CARVALLO JIMÉNEZ | H22: 650343 | I22: -15087471
B23: 45869 | C23: 3303 | D23: Glosa : APERTURA TDC JS. CARVALLO FEB | E23: JUAN CARVALLO JIMÉNEZ | H23: 20962 | I23: -21625929
B24: 45869 | C24: 3459 | D24: Glosa : Spend Money CC Expense ABRIL-JULIO 2114-11 | E24: JUAN CARVALLO JIMÉNEZ | H24: 118170 | I24: -26517189 | J24: ?
B25: 45869 | C25: 3459 | D25: Glosa : Spend Money CC Expense ABRIL-JULIO 2114-11 | E25: JUAN CARVALLO JIMÉNEZ | H25: 289936 | I25: -26807125 | J25: ?
B28: Fec. Doc. | C28: Voucher | E28: Titular | F28: T.Doc/Nro | G28: Debe | H28: Haber | I28: Acumulado
B29: 45701 | C29: 2282 | D29: Glosa : Pago Tarjeta de Credito | E29: JUAN CARVALLO JIMÉNEZ | G29: 650343 | I29: =+G29 -> 650343
B30: 45772 | C30: 2555 | D30: Glosa : TDC CLP JUAN CARVALLO | E30: JUAN CARVALLO JIMÉNEZ | H30: 122074 | I30: =I29+G30-H30 -> 528269
B31: 45792 | C31: 2746 | D31: Glosa : Bank Transfer to CC Sebastián Carvallo. | E31: JUAN CARVALLO JIMÉNEZ | G31: 72314 | I31: =I30+G31-H31 -> 600583
B32: 45805 | C32: 2911 | D32: Glosa : TDC CLP JUAN sebastian CARVALLO | E32: JUAN CARVALLO JIMÉNEZ | H32: 161109 | I32: =I31+G32-H32 -> 439474
B33: 45805 | C33: 3504 | D33: Glosa : TDC CLP JUAN sebastian CARVALLO | E33: JUAN CARVALLO JIMÉNEZ | H33: 229285 | I33: =I32+G33-H33 -> 210189
B34: 45813 | C34: 2814 | D34: Glosa : Payment: ER - Sebastián Carvallo25.5 - Reimbursable Expense - Lundin Mining - Cand... | 25.5 - Reimbursable Expense - Lundin Mining - Cand... | E34: JUAN CARVALLO JIMÉNEZ | G34: 43000 | I34: =I33+G34-H34 -> 253189
B35: 45820 | C35: 2862 | D35: Glosa : Bank Transfer to CC Sebastián Carvallo. | E35: JUAN CARVALLO JIMÉNEZ | G35: 210396 | I35: =I34+G35-H35 -> 463585
B36: 45867 | C36: 3094 | D36: Glosa : TDC CLP JUAN sebastian CARVALLO | E36: JUAN CARVALLO JIMÉNEZ | H36: 293855 | I36: =I35+G36-H36 -> 169730
B37: 45869 | C37: 3286 | D37: Glosa : APERTURA TDC J. SEBASTIAN C. ENERO | E37: JUAN CARVALLO JIMÉNEZ | H37: 650343 | I37: =I36+G37-H37 -> -480613
B38: 45869 | C38: 3303 | D38: Glosa : APERTURA TDC JS. CARVALLO FEB | E38: JUAN CARVALLO JIMÉNEZ | H38: 20962 | I38: =I37+G38-H38 -> -501575
B39: 45869 | C39: 3459 | D39: Glosa : Spend Money CC Expense ABRIL-JULIO 2114-11 | E39: JUAN CARVALLO JIMÉNEZ | H39: 118170 | I39: =I38+G39-H39 -> -619745
B40: 45869 | C40: 3459 | D40: Glosa : Spend Money CC Expense ABRIL-JULIO 2114-11 | E40: JUAN CARVALLO JIMÉNEZ | H40: 289936 | I40: =I39+G40-H40 -> -909681
B41: 45869 | C41: 3574 | D41: Glosa : compensa prov | E41: JUAN CARVALLO JIMÉNEZ | G41: 594864 | I41: =I40+G41-H41 -> -314817
B42: 45729 | C42: 2343 | D42: Glosa : Pago tarjeta de Credito | E42: JUAN CARVALLO JIMÉNEZ | G42: 20962 | I42: =I41+G42-H42 -> -293855
B43: 45882 | C43: 3259 | D43: Glosa : Sebastian´s cc payment | E43: JUAN SEBASTIAN CARVALLO JIMÉNEZ | G43: 293855 | I43: =I42+G43-H43 -> 0
B44: 45897 | C44: 3504 | D44: Glosa : TDC CLP JUAN sebastian CARVALLO | E44: JUAN SEBASTIAN CARVALLO JIMÉNEZ | H44: 37917 | I44: =I43+G44-H44 -> -37917
B45: 45897 | D45: provision | G45: 37919 | H45: 71641 | I45: =I44+G45-H45 -> -71639
...

Sheet 11_X
A1: Account Code | B1: Account | C1: Date | D1: Source | E1: Description | F1: Reference | G1: Debit | H1: Credit
A2: 2114-11 | B2: CC Sebastián Carvallo | C2: 45677 | D2: Payable Payment | E2: Payment: INMOBILIARIA COLIPI SPA | F2: F/86375 | G2: 0 | H2: 243096 | I2: =+G2-H2 -> -243096
A3: 2114-11 | B3: CC Sebastián Carvallo | C3: 45677 | D3: Spend Money | E3: CC Expense | F3: Cena 20-Enero | G3: 0 | H3: 26840 | I3: =I2+G3-H3 -> -269936
A4: 2114-11 | B4: CC Sebastián Carvallo | C4: 45678 | D4: Spend Money | E4: CC Expense | F4: Cena 21-Enero | G4: 0 | H4: 26840 | I4: =I3+G4-H4 -> -296776
A5: 2114-11 | B5: CC Sebastián Carvallo | C5: 45684 | D5: Payable Payment | E5: Payment: INMOBILIARIA COLIPI SPA | F5: F/87375 | G5: 0 | H5: 303858 | I5: =I4+G5-H5 -> -600634
A6: 2114-11 | B6: CC Sebastián Carvallo | C6: 45684 | D6: Spend Money | E6: CC Expense | F6: Cena 27-Enero | G6: 0 | H6: 19960 | I6: =I5+G6-H6 -> -620594
A7: 2114-11 | B7: CC Sebastián Carvallo | C7: 45684 | D7: Adjustment | E7: Reconciliation adjustment | G7: 270 | H7: 0 | I7: =I6+G7-H7 -> -620324
A8: 2114-11 | B8: CC Sebastián Carvallo | C8: 45685 | D8: Spend Money | E8: CC Expense | F8: Cena 28-Enero | G8: 0 | H8: 26180 | I8: =I7+G8-H8 -> -646504
A9: 2114-11 | B9: CC Sebastián Carvallo | C9: 45686 | D9: Spend Money | E9: Banco De Chile | G9: 0 | H9: 3839 | I9: =I8+G9-H9 -> -650343
A10: 2114-11 | B10: CC Sebastián Carvallo | C10: 45686 | D10: Spend Money | E10: CC Expense | F10: Cena 29-Enero | G10: 0 | H10: 17100 | I10: =I9+G10-H10 -> -667443
A11: 2114-11 | B11: CC Sebastián Carvallo | C11: 45701 | D11: Bank Transfer | E11: Bank Transfer from Citibank - CLP to CC Sebastián Carvallo | F11: CC payment Sebas | G11: 650343 | H11: 0 | I11: =I10+G11-H11 -> -17100
A12: 2114-11 | B12: CC Sebastián Carvallo | C12: 45714 | D12: Spend Money | E12: Banco De Chile | G12: 0 | H12: 3862 | I12: =I11+G12-H12 -> -20962
A13: 2114-11 | B13: CC Sebastián Carvallo | C13: 45729 | D13: Bank Transfer | E13: Bank Transfer from Citibank - CLP to CC Sebastián Carvallo | F13: SC´s credit card payment | G13: 20962 | H13: 0 | I13: =I12+G13-H13 -> 0
A14: 2114-11 | B14: CC Sebastián Carvallo | C14: 45769 | D14: Spend Money | E14: CC Expense | F14: Almuerzo K. Bollmann - A. Gonzalez - S. Carvallo | G14: 0 | H14: 19500 | I14: =I13+G14-H14 -> -19500
A15: 2114-11 | B15: CC Sebastián Carvallo | C15: 45771 | D15: Spend Money | E15: CC Expense | F15: Almuerzo K. Bollmann - A. Gonzalez - S. Carvallo | G15: 0 | H15: 98670 | I15: =I14+G15-H15 -> -118170
A16: 2114-11 | B16: CC Sebastián Carvallo | C16: 45772 | D16: Spend Money | E16: Banco De Chile | G16: 0 | H16: 3904 | I16: =I15+G16-H16 -> -122074
A17: 2114-11 | B17: CC Sebastián Carvallo | C17: 45782 | D17: Spend Money | E17: CC Expense | F17: Taxi aeropuerto a Hotel Chagall | G17: 0 | H17: 10000 | I17: =I16+G17-H17 -> -132074
A18: 2114-11 | B18: CC Sebastián Carvallo | C18: 45785 | D18: Payable Payment | E18: Payment: Hotelera Domus Ltda | F18: Pago restante | G18: 0 | H18: 49287 | I18: =I17+G18-H18 -> -181361
A19: 2114-11 | B19: CC Sebastián Carvallo | C19: 45789 | D19: Spend Money | E19: CC Expense | F19: Taxi Aeropuerto a Hotel | G19: 0 | H19: 10000 | I19: =I18+G19-H19 -> -191361
A20: 2114-11 | B20: CC Sebastián Carvallo | C20: 45789 | D20: Spend Money | E20: CC Expense | F20: Almuerzo da 1 | G20: 0 | H20: 21065 | I20: =I19+G20-H20 -> -212426
A21: 2114-11 | B21: CC Sebastián Carvallo | C21: 45791 | D21: Spend Money | E21: CC Expense | F21: Cena da 3 | G21: 0 | H21: 16115 | I21: =I20+G21-H21 -> -228541
A22: 2114-11 | B22: CC Sebastián Carvallo | C22: 45792 | D22: Bank Transfer | E22: Bank Transfer from Citibank - CLP to CC Sebastián Carvallo | F22: SCs credit card payment | G22: 72314 | H22: 0 | I22: =I21+G22-H22 -> -156227
A23: 2114-11 | B23: CC Sebastián Carvallo | C23: 45792 | D23: Spend Money | E23: CC Expense | F23: Cenas das 1 y 2 | G23: 0 | H23: 50251 | I23: =I22+G23-H23 -> -206478
A24: 2114-11 | B24: CC Sebastián Carvallo | C24: 45805 | D24: Spend Money | E24: Banco De Chile | G24: 0 | H24: 3918 | I24: =I23+G24-H24 -> -210396
